Workbook

Sheet 법정산식 총량
A1: 사업구역 | B1: 시군 | C1: 시군 | D1: 인구규모 | E1: 인구규모 | F1: 부제 | G1: 인구수 | H1: 총면허대수(23.12) | K1: 등록대비 TIMS 수집율 | N1: 거리실차율 | R1: 시간실차율 | V1: 가동률(8h 1대) | Z1: 가동률(10h 1대) | AD1: 법정산식 총량 | AJ1: 기본총량 증차 | AM1: 택시 면허당 인구수 | AO1: 자율조정 (10%) | AP1: 최종 총량 (거리) | AQ1: 과잉 공급수 | AS1: 자율조정 (10%) | AT1: 최종 총량 (거리+시간) | AU1: 과잉 공급수 | AW1: 자율조정 (15%) | AX1: 최종 총량 (거리+시간) | AY1: 과잉 공급수 | BA1: 자율조정 (20%) | BB1: 최종 총량 (거리+시간) | BC1: 과잉 공급수
N2: 목표 | O2: 현재 | R2: 목표 | S2: 현재 | V2: 안정적 | W2: 현재 | Z2: 안정적 | AA2: 현재 | AD2: 가동률 8h 1대 적용시 | AF2: 보정결과 | AJ2: 기본총량 증감
H3: 법인 | I3: 개인 | J3: 합계 | K3: 법인 | L3: 개인 | M3: 합계 | O3: 법인 | P3: 개인 | Q3: 합계 | S3: 법인 | T3: 개인 | U3: 합계 | W3: 법인 | X3: 개인 | Y3: 합계 | AA3: 법인 | AB3: 개인 | AC3: 합계 | AD3: 거리만 | AE3: 거리+시간 | AG3: 도농반영 | AJ3: 거리만 | AK3: 보정결과
A4: 강원특별자치도 강릉시 | B4: 강릉시 | C4: 시 | D4: 20~50만 이하 | E4: 50만 이하 | F4: 10부 | G4: 210080 | H4: 428 | I4: 770 | J4: 1198 | K4: =기초자료!AV4/기초자료!I4 -> 0.75597444 | L4: =기초자료!AW4/기초자료!J4 -> 0.90460556 | M4: =기초자료!AX4/기초자료!K4 -> 0.85150529 | N4: =VLOOKUP(E4,'목표실차율, 안정적가동률'!$A$3:$C$9,3,FALSE) -> 0.49 | O4: =기초자료!CI4 -> 0.51983472 | P4: =기초자료!CJ4 -> 0.48465122 | Q4: =기초자료!CK4 -> 0.49581075 | R4: =VLOOKUP(E4,'목표실차율, 안정적가동률'!$F$3:$G$9,2,FALSE) -> 0.34 | S4: =기초자료!DV4 -> 0.36442986 | T4: =기초자료!DW4 -> 0.35796043 | U4: =기초자료!DX4 -> 0.36001241 | V4: =VLOOKUP(F4,'목표실차율, 안정적가동률'!$J$3:$L$6,3,FALSE) -> 0.88 | W4: =기초자료!FI4 -> 0.80614377 | X4: =기초자료!FJ4 -> 0.75131658 | Y4: =기초자료!FK4 -> 0.76870671 | Z4: =VLOOKUP(F4,'목표실차율, 안정적가동률'!$J$3:$L$6,3,FALSE) -> 0.88 | AA4: =기초자료!GP4 -> #DIV/0! | AB4: =기초자료!GQ4 -> #DIV/0! | AC4: =기초자료!GR4 -> 0 | AD4: =ROUND(J4*(Q4/N4)*(Y4/V4),0) -> 1059 | AE4: =ROUND(J4*(Q4/N4*0.8+U4/R4*0.2)*(Y4/V4),0) -> 1069 | AF4: =AG4 -> 1186.582 | AG4: =VLOOKUP(B4,'[1]Jan-Dec'!$B$2:$AY$61,50,0) -> 1186.582 | AH4: =ROUND(J4*(Q4/N4*0.8+U4/R4*0.2)*(AC4/Z4),0) -> 0 | AJ4: =J4-AD4 -> 139 | AK4: =J4-AF4 -> 11.41797 | AM4: =ROUND(G4/J4,0) -> 175 | AO4: =IF(AM4>312,ROUND(AD4*0.1,0),0) -> 0 | AP4: =AD4+AO4 -> 1059 | AQ4: =J4-AP4 -> 139 | AS4: =IF(AM4>312,ROUND(AF4*0.1,0),0) -> 0 | AT4: =AS4+AF4 -> 1186.582 | AU4: =J4-AT4 -> 11.41797 | AW4: =IF(AF4*1.15>J4,ROUND(AF4*0.15,0),0) -> 178 | AX4: =AF4+AW4 -> 1364.582 | AY4: =J4-AX4 -> -166.58203 | BA4: =IF(AF4*1.2>J4,ROUND(AF4*0.2,0),0) -> 237 | BB4: =AF4+BA4 -> 1423.582 | BC4: =J4-BB4 -> -225.58203
A5: 강원특별자치도 고성군 | B5: 고성군 | C5: 군 | D5: 군지역 | E5: 군지역 | F5: 10부 | G5: 27329 | H5: 25 | I5: 56 | J5: 81 | K5: =기초자료!AV5/기초자료!I5 -> 0.47971165 | L5: =기초자료!AW5/기초자료!J5 -> 0.88424153 | M5: =기초자료!AX5/기초자료!K5 -> 0.75938663 | N5: =VLOOKUP(E5,'목표실차율, 안정적가동률'!$A$3:$C$9,3,FALSE) -> 0.46 | O5: =기초자료!CI5 -> 0.27847735 | P5: =기초자료!CJ5 -> 0.3330261 | Q5: =기초자료!CK5 -> 0.32239062 | R5: =VLOOKUP(E5,'목표실차율, 안정적가동률'!$F$3:$G$9,2,FALSE) -> 0.25 | S5: =기초자료!DV5 -> 0.18407692 | T5: =기초자료!DW5 -> 0.17514231 | U5: =기초자료!DX5 -> 0.17688431 | V5: =VLOOKUP(F5,'목표실차율, 안정적가동률'!$J$3:$L$6,3,FALSE) -> 0.88 | W5: =기초자료!FI5 -> 0.87962612 | X5: =기초자료!FJ5 -> 0.86983864 | Y5: =기초자료!FK5 -> 0.87174693 | Z5: =VLOOKUP(F5,'목표실차율, 안정적가동률'!$J$3:$L$6,3,FALSE) -> 0.88 | AA5: =기초자료!GP5 -> #DIV/0! | AB5: =기초자료!GQ5 -> #DIV/0! | AC5: =기초자료!GR5 -> 0 | AD5: =ROUND(J5*(Q5/N5)*(Y5/V5),0) -> 56 | AE5: =ROUND(J5*(Q5/N5*0.8+U5/R5*0.2)*(Y5/V5),0) -> 56 | AF5: =AE5 -> 56 | AG5: =VLOOKUP(B5,'[1]Jan-Dec'!$B$2:$AY$61,50,0) -> #N/A | AH5: =ROUND(J5*(Q5/N5*0.8+U5/R5*0.2)*(AC5/Z5),0) -> 0 | AJ5: =J5-AD5 -> 25 | AK5: =J5-AF5 -> 25 | AM5: =ROUND(G5/J5,0) -> 337 | AO5: =IF(AM5>312,ROUND(AD5*0.1,0),0) -> 6 | AP5: =AD5+AO5 -> 62 | AQ5: =J5-AP5 -> 19 | AS5: =IF(AM5>312,ROUND(AF5*0.1,0),0) -> 6 | AT5: =AS5+AF5 -> 62 | AU5: =J5-AT5 -> 19 | AW5: =IF(AF5*1.15>J5,ROUND(AF5*0.15,0),0) -> 0 | AX5: =AF5+AW5 -> 56 | AY5: =J5-AX5 -> 25 | BA5: =IF(AF5*1.2>J5,ROUND(AF5*0.2,0),0) -> 0 | BB5: =AF5+BA5 -> 56 | BC5: =J5-BB5 -> 25
A6: 강원특별자치도 동해시 | B6: 동해시 | C6: 시 | D6: 20만 이하 | E6: 20만 이하 | F6: 10부 | G6: 88851 | H6: 141 | I6: 341 | J6: 482 | K6: =기초자료!AV6/기초자료!I6 -> 0.71994029 | L6: =기초자료!AW6/기초자료!J6 -> 0.77802758 | M6: =기초자료!AX6/기초자료!K6 -> 0.76103524 | N6: =VLOOKUP(E6,'목표실차율, 안정적가동률'!$A$3:$C$9,3,FALSE) -> 0.48 | O6: =기초자료!CI6 -> 0.41687465 | P6: =기초자료!CJ6 -> 0.4712483 | Q6: =기초자료!CK6 -> 0.45620122 | R6: =VLOOKUP(E6,'목표실차율, 안정적가동률'!$F$3:$G$9,2,FALSE) -> 0.25 | S6: =기초자료!DV6 -> 0.21388749 | T6: =기초자료!DW6 -> 0.25788684 | U6: =기초자료!DX6 -> 0.24571069 | V6: =VLOOKUP(F6,'목표실차율, 안정적가동률'!$J$3:$L$6,3,FALSE) -> 0.88 | W6: =기초자료!FI6 -> 0.84899474 | X6: =기초자료!FJ6 -> 0.79622728 | Y6: =기초자료!FK6 -> 0.81082987 | Z6: =VLOOKUP(F6,'목표실차율, 안정적가동률'!$J$3:$L$6,3,FALSE) -> 0.88 | AA6: =기초자료!GP6 -> #DIV/0! | AB6: =기초자료!GQ6 -> #DIV/0! | AC6: =기초자료!GR6 -> 0 | AD6: =ROUND(J6*(Q6/N6)*(Y6/V6),0) -> 422 | AE6: =ROUND(J6*(Q6/N6*0.8+U6/R6*0.2)*(Y6/V6),0) -> 425 | AF6: =AE6 -> 425 | AG6: =VLOOKUP(B6,'[1]Jan-Dec'!$B$2:$AY$61,50,0) -> #N/A | AH6: =ROUND(J6*(Q6/N6*0.8+U6/R6*0.2)*(AC6/Z6),0) -> 0 | AJ6: =J6-AD6 -> 60 | AK6: =J6-AF6 -> 57 | AM6: =ROUND(G6/J6,0) -> 184 | AO6: =IF(AM6>312,ROUND(AD6*0.1,0),0) -> 0 | AP6: =AD6+AO6 -> 422 | AQ6: =J6-AP6 -> 60 | AS6: =IF(AM6>312,ROUND(AF6*0.1,0),0) -> 0 | AT6: =AS6+AF6 -> 425 | AU6: =J6-AT6 -> 57 | AW6: =IF(AF6*1.15>J6,ROUND(AF6*0.15,0),0) -> 64 | AX6: =AF6+AW6 -> 489 | AY6: =J6-AX6 -> -7 | BA6: =IF(AF6*1.2>J6,ROUND(AF6*0.2,0),0) -> 85 | BB6: =AF6+BA6 -> 510 | BC6: =J6-BB6 -> -28
A7: 강원특별자치도 삼척시 | B7: 삼척시 | C7: 시 | D7: 20만 이하 | E7: 20만 이하 | F7: 10부 | G7: 63063 | H7: 99 | I7: 157 | J7: 256 | K7: =기초자료!AV7/기초자료!I7 -> 0.71135193 | L7: =기초자료!AW7/기초자료!J7 -> 0.86511861 | M7: =기초자료!AX7/기초자료!K7 -> 0.80565415 | N7: =VLOOKUP(E7,'목표실차율, 안정적가동률'!$A$3:$C$9,3,FALSE) -> 0.48 | O7: =기초자료!CI7 -> 0.33946257 | P7: =기초자료!CJ7 -> 0.41743062 | Q7: =기초자료!CK7 -> 0.39080819 | R7: =VLOOKUP(E7,'목표실차율, 안정적가동률'!$F$3:$G$9,2,FALSE) -> 0.25 | S7: =기초자료!DV7 -> 0.2079556 | T7: =기초자료!DW7 -> 0.21415278 | U7: =기초자료!DX7 -> 0.21203673 | V7: =VLOOKUP(F7,'목표실차율, 안정적가동률'!$J$3:$L$6,3,FALSE) -> 0.88 | W7: =기초자료!FI7 -> 0.81873796 | X7: =기초자료!FJ7 -> 0.83529014 | Y7: =기초자료!FK7 -> 0.82963835 | Z7: =VLOOKUP(F7,'목표실차율, 안정적가동률'!$J$3:$L$6,3,FALSE) -> 0.88 | AA7: =기초자료!GP7 -> #DIV/0! | AB7: =기초자료!GQ7 -> #DIV/0! | AC7: =기초자료!GR7 -> 0 | AD7: =ROUND(J7*(Q7/N7)*(Y7/V7),0) -> 197 | AE7: =ROUND(J7*(Q7/N7*0.8+U7/R7*0.2)*(Y7/V7),0) -> 198 | AF7: =AG7 -> 204.96535 | AG7: =VLOOKUP(B7,'[1]Jan-Dec'!$B$2:$AY$61,50,0) -> 204.96535 | AH7: =ROUND(J7*(Q7/N7*0.8+U7/R7*0.2)*(AC7/Z7),0) -> 0 | AJ7: =J7-AD7 -> 59 | AK7: =J7-AF7 -> 51.034647 | AM7: =ROUND(G7/J7,0) -> 246 | AO7: =IF(AM7>312,ROUND(AD7*0.1,0),0) -> 0 | AP7: =AD7+AO7 -> 197 | AQ7: =J7-AP7 -> 59 | AS7: =IF(AM7>312,ROUND(AF7*0.1,0),0) -> 0 | AT7: =AS7+AF7 -> 204.96535 | AU7: =J7-AT7 -> 51.034647 | AW7: =IF(AF7*1.15>J7,ROUND(AF7*0.15,0),0) -> 0 | AX7: =AF7+AW7 -> 204.96535 | AY7: =J7-AX7 -> 51.034647 | BA7: =IF(AF7*1.2>J7,ROUND(AF7*0.2,0),0) -> 0 | BB7: =AF7+BA7 -> 204.96535 | BC7: =J7-BB7 -> 51.034647
A8: 강원특별자치도 속초시 | B8: 속초시 | C8: 시 | D8: 20만 이하 | E8: 20만 이하 | F8: 10부 | G8: 82226 | H8: 172 | I8: 411 | J8: 583 | K8: =기초자료!AV8/기초자료!I8 -> 0.81327783 | L8: =기초자료!AW8/기초자료!J8 -> 0.88064384 | M8: =기초자료!AX8/기초자료!K8 -> 0.86076913 | N8: =VLOOKUP(E8,'목표실차율, 안정적가동률'!$A$3:$C$9,3,FALSE) -> 0.48 | O8: =기초자료!CI8 -> 0.4174079 | P8: =기초자료!CJ8 -> 0.42418201 | Q8: =기초자료!CK8 -> 0.42229374 | R8: =VLOOKUP(E8,'목표실차율, 안정적가동률'!$F$3:$G$9,2,FALSE) -> 0.25 | S8: =기초자료!DV8 -> 0.29344994 | T8: =기초자료!DW8 -> 0.30901623 | U8: =기초자료!DX8 -> 0.30467716 | V8: =VLOOKUP(F8,'목표실차율, 안정적가동률'!$J$3:$L$6,3,FALSE) -> 0.88 | W8: =기초자료!FI8 -> 0.82381109 | X8: =기초자료!FJ8 -> 0.75499186 | Y8: =기초자료!FK8 -> 0.7741751 | Z8: =VLOOKUP(F8,'목표실차율, 안정적가동률'!$J$3:$L$6,3,FALSE) -> 0.88 | AA8: =기초자료!GP8 -> #DIV/0! | AB8: =기초자료!GQ8 -> #DIV/0! | AC8: =기초자료!GR8 -> 0 | AD8: =ROUND(J8*(Q8/N8)*(Y8/V8),0) -> 451 | AE8: =ROUND(J8*(Q8/N8*0.8+U8/R8*0.2)*(Y8/V8),0) -> 486 | AF8: =AE8 -> 486 | AG8: =VLOOKUP(B8,'[1]Jan-Dec'!$B$2:$AY$61,50,0) -> #N/A | AH8: =ROUND(J8*(Q8/N8*0.8+U8/R8*0.2)*(AC8/Z8),0) -> 0 | AJ8: =J8-AD8 -> 132 | AK8: =J8-AF8 -> 97 | AM8: =ROUND(G8/J8,0) -> 141 | AO8: =IF(AM8>312,ROUND(AD8*0.1,0),0) -> 0 | AP8: =AD8+AO8 -> 451 | AQ8: =J8-AP8 -> 132 | AS8: =IF(AM8>312,ROUND(AF8*0.1,0),0) -> 0 | AT8: =AS8+AF8 -> 486 | AU8: =J8-AT8 -> 97 | AW8: =IF(AF8*1.15>J8,ROUND(AF8*0.15,0),0) -> 0 | AX8: =AF8+AW8 -> 486 | AY8: =J8-AX8 -> 97 | BA8: =IF(AF8*1.2>J8,ROUND(AF8*0.2,0),0) -> 97 | BB8: =AF8+BA8 -> 583 | BC8: =J8-BB8 -> 0
A9: 강원특별자치도 양구군 | B9: 양구군 | C9: 군 | D9: 군지역 | E9: 군지역 | F9: 10부 | G9: 21192 | H9: 14 | I9: 26 | J9: 40 | K9: =기초자료!AV9/기초자료!I9 -> 0.94856079 | L9: =기초자료!AW9/기초자료!J9 -> 0.8917495 | M9: =기초자료!AX9/기초자료!K9 -> 0.91163345 | N9: =VLOOKUP(E9,'목표실차율, 안정적가동률'!$A$3:$C$9,3,FALSE) -> 0.46 | O9: =기초자료!CI9 -> 0.38216236 | P9: =기초자료!CJ9 -> 0.37463517 | Q9: =기초자료!CK9 -> 0.3773764 | R9: =VLOOKUP(E9,'목표실차율, 안정적가동률'!$F$3:$G$9,2,FALSE) -> 0.25 | S9: =기초자료!DV9 -> 0.22785312 | T9: =기초자료!DW9 -> 0.24964832 | U9: =기초자료!DX9 -> 0.241711 | V9: =VLOOKUP(F9,'목표실차율, 안정적가동률'!$J$3:$L$6,3,FALSE) -> 0.88 | W9: =기초자료!FI9 -> 0.75365168 | X9: =기초자료!FJ9 -> 0.67834504 | Y9: =기초자료!FK9 -> 0.70577001 | Z9: =VLOOKUP(F9,'목표실차율, 안정적가동률'!$J$3:$L$6,3,FALSE) -> 0.88 | AA9: =기초자료!GP9 -> #DIV/0! | AB9: =기초자료!GQ9 -> #DIV/0! | AC9: =기초자료!GR9 -> 0 | AD9: =ROUND(J9*(Q9/N9)*(Y9/V9),0) -> 26 | AE9: =ROUND(J9*(Q9/N9*0.8+U9/R9*0.2)*(Y9/V9),0) -> 27 | AF9: =AE9 -> 27 | AG9: =VLOOKUP(B9,'[1]Jan-Dec'!$B$2:$AY$61,50,0) -> #N/A | AH9: =ROUND(J9*(Q9/N9*0.8+U9/R9*0.2)*(AC9/Z9),0) -> 0 | AJ9: =J9-AD9 -> 14 | AK9: =J9-AF9 -> 13 | AM9: =ROUND(G9/J9,0) -> 530 | AO9: =IF(AM9>312,ROUND(AD9*0.1,0),0) -> 3 | AP9: =AD9+AO9 -> 29 | AQ9: =J9-AP9 -> 11 | AS9: =IF(AM9>312,ROUND(AF9*0.1,0),0) -> 3 | AT9: =AS9+AF9 -> 30 | AU9: =J9-AT9 -> 10 | AW9: =IF(AF9*1.15>J9,ROUND(AF9*0.15,0),0) -> 0 | AX9: =AF9+AW9 -> 27 | AY9: =J9-AX9 -> 13 | BA9: =IF(AF9*1.2>J9,ROUND(AF9*0.2,0),0) -> 0 | BB9: =AF9+BA9 -> 27 | BC9: =J9-BB9 -> 13
A10: 강원특별자치도 양양군 | B10: 양양군 | C10: 군 | D10: 군지역 | E10: 군지역 | F10: 10부 | G10: 27750 | H10: 33 | I10: 58 | J10: 91 | K10: =기초자료!AV10/기초자료!I10 -> 0.95878507 | L10: =기초자료!AW10/기초자료!J10 -> 0.9380607 | M10: =기초자료!AX10/기초자료!K10 -> 0.94337464 | N10: =VLOOKUP(E10,'목표실차율, 안정적가동률'!$A$3:$C$9,3,FALSE) -> 0.46 | O10: =기초자료!CI10 -> 0.38188773 | P10: =기초자료!CJ10 -> 0.39136493 | Q10: =기초자료!CK10 -> 0.38889518 | R10: =VLOOKUP(E10,'목표실차율, 안정적가동률'!$F$3:$G$9,2,FALSE) -> 0.25 | S10: =기초자료!DV10 -> 0.16403221 | T10: =기초자료!DW10 -> 0.19841358 | U10: =기초자료!DX10 -> 0.18945383 | V10: =VLOOKUP(F10,'목표실차율, 안정적가동률'!$J$3:$L$6,3,FALSE) -> 0.88 | W10: =기초자료!FI10 -> 0.8791972 | X10: =기초자료!FJ10 -> 0.80982347 | Y10: =기초자료!FK10 -> 0.82790219 | Z10: =VLOOKUP(F10,'목표실차율, 안정적가동률'!$J$3:$L$6,3,FALSE) -> 0.88 | AA10: =기초자료!GP10 -> #DIV/0! | AB10: =기초자료!GQ10 -> #DIV/0! | AC10: =기초자료!GR10 -> 0 | AD10: =ROUND(J10*(Q10/N10)*(Y10/V10),0) -> 72 | AE10: =ROUND(J10*(Q10/N10*0.8+U10/R10*0.2)*(Y10/V10),0) -> 71 | AF10: =AE10 -> 71 | AG10: =VLOOKUP(B10,'[1]Jan-Dec'!$B$2:$AY$61,50,0) -> #N/A | AH10: =ROUND(J10*(Q10/N10*0.8+U10/R10*0.2)*(AC10/Z10),0) -> 0 | AJ10: =J10-AD10 -> 19 | AK10: =J10-AF10 -> 20 | AM10: =ROUND(G10/J10,0) -> 305 | AO10: =IF(AM10>312,ROUND(AD10*0.1,0),0) -> 0 | AP10: =AD10+AO10 -> 72 | AQ10: =J10-AP10 -> 19 | AS10: =IF(AM10>312,ROUND(AF10*0.1,0),0) -> 0 | AT10: =AS10+AF10 -> 71 | AU10: =J10-AT10 -> 20 | AW10: =IF(AF10*1.15>J10,ROUND(AF10*0.15,0),0) -> 0 | AX10: =AF10+AW10 -> 71 | AY10: =J10-AX10 -> 20 | BA10: =IF(AF10*1.2>J10,ROUND(AF10*0.2,0),0) -> 0 | BB10: =AF10+BA10 -> 71 | BC10: =J10-BB10 -> 20
A11: 강원특별자치도 영월군 | B11: 영월군 | C11: 군 | D11: 군지역 | E11: 군지역 | F11: 10부 | G11: 37480 | H11: 22 | I11: 83 | J11: 105 | K11: =기초자료!AV11/기초자료!I11 -> 0.67122757 | L11: =기초자료!AW11/기초자료!J11 -> 0.75341146 | M11: =기초자료!AX11/기초자료!K11 -> 0.73619198 | N11: =VLOOKUP(E11,'목표실차율, 안정적가동률'!$A$3:$C$9,3,FALSE) -> 0.46 | O11: =기초자료!CI11 -> 0.25714385 | P11: =기초자료!CJ11 -> 0.24761513 | Q11: =기초자료!CK11 -> 0.24943544 | R11: =VLOOKUP(E11,'목표실차율, 안정적가동률'!$F$3:$G$9,2,FALSE) -> 0.25 | S11: =기초자료!DV11 -> 0.1436451 | T11: =기초자료!DW11 -> 0.17169505 | U11: =기초자료!DX11 -> 0.16633654 | V11: =VLOOKUP(F11,'목표실차율, 안정적가동률'!$J$3:$L$6,3,FALSE) -> 0.88 | W11: =기초자료!FI11 -> 0.80169838 | X11: =기초자료!FJ11 -> 0.77194878 | Y11: =기초자료!FK11 -> 0.77763198 | Z11: =VLOOKUP(F11,'목표실차율, 안정적가동률'!$J$3:$L$6,3,FALSE) -> 0.88 | AA11: =기초자료!GP11 -> #DIV/0! | AB11: =기초자료!GQ11 -> #DIV/0! | AC11: =기초자료!GR11 -> 0 | AD11: =ROUND(J11*(Q11/N11)*(Y11/V11),0) -> 50 | AE11: =ROUND(J11*(Q11/N11*0.8+U11/R11*0.2)*(Y11/V11),0) -> 53 | AF11: =AE11 -> 53 | AG11: =VLOOKUP(B11,'[1]Jan-Dec'!$B$2:$AY$61,50,0) -> #N/A | AH11: =ROUND(J11*(Q11/N11*0.8+U11/R11*0.2)*(AC11/Z11),0) -> 0 | AJ11: =J11-AD11 -> 55 | AK11: =J11-AF11 -> 52 | AM11: =ROUND(G11/J11,0) -> 357 | AO11: =IF(AM11>312,ROUND(AD11*0.1,0),0) -> 5 | AP11: =AD11+AO11 -> 55 | AQ11: =J11-AP11 -> 50 | AS11: =IF(AM11>312,ROUND(AF11*0.1,0),0) -> 5 | AT11: =AS11+AF11 -> 58 | AU11: =J11-AT11 -> 47 | AW11: =IF(AF11*1.15>J11,ROUND(AF11*0.15,0),0) -> 0 | AX11: =AF11+AW11 -> 53 | AY11: =J11-AX11 -> 52 | BA11: =IF(AF11*1.2>J11,ROUND(AF11*0.2,0),0) -> 0 | BB11: =AF11+BA11 -> 53 | BC11: =J11-BB11 -> 52
A12: 강원특별자치도 원주시 | B12: 원주시 | C12: 시 | D12: 20~50만 이하 | E12: 50만 이하 | F12: 10부 | G12: 361316 | H12: 629 | I12: 1235 | J12: 1864 | K12: =기초자료!AV12/기초자료!I12 -> 0.9289171 | L12: =기초자료!AW12/기초자료!J12 -> 0.89091443 | M12: =기초자료!AX12/기초자료!K12 -> 0.90313629 | N12: =VLOOKUP(E12,'목표실차율, 안정적가동률'!$A$3:$C$9,3,FALSE) -> 0.49 | O12: =기초자료!CI12 -> 0.5271982 | P12: =기초자료!CJ12 -> 0.43643 | Q12: =기초자료!CK12 -> 0.46645483 | R12: =VLOOKUP(E12,'목표실차율, 안정적가동률'!$F$3:$G$9,2,FALSE) -> 0.34 | S12: =기초자료!DV12 -> 0.35171941 | T12: =기초자료!DW12 -> 0.30163138 | U12: =기초자료!DX12 -> 0.31819979 | V12: =VLOOKUP(F12,'목표실차율, 안정적가동률'!$J$3:$L$6,3,FALSE) -> 0.88 | W12: =기초자료!FI12 -> 0.82566501 | X12: =기초자료!FJ12 -> 0.74674709 | Y12: =기초자료!FK12 -> 0.77285202 | Z12: =VLOOKUP(F12,'목표실차율, 안정적가동률'!$J$3:$L$6,3,FALSE) -> 0.88 | AA12: =기초자료!GP12 -> #DIV/0! | AB12: =기초자료!GQ12 -> #DIV/0! | AC12: =기초자료!GR12 -> 0 | AD12: =ROUND(J12*(Q12/N12)*(Y12/V12),0) -> 1558 | AE12: =ROUND(J12*(Q12/N12*0.8+U12/R12*0.2)*(Y12/V12),0) -> 1553 | AF12: =AG12 -> 1661.0172 | AG12: =VLOOKUP(B12,'[1]Jan-Dec'!$B$2:$AY$61,50,0) -> 1661.0172 | AH12: =ROUND(J12*(Q12/N12*0.8+U12/R12*0.2)*(AC12/Z12),0) -> 0 | AJ12: =J12-AD12 -> 306 | AK12: =J12-AF12 -> 202.98281 | AM12: =ROUND(G12/J12,0) -> 194 | AO12: =IF(AM12>312,ROUND(AD12*0.1,0),0) -> 0 | AP12: =AD12+AO12 -> 1558 | AQ12: =J12-AP12 -> 306 | AS12: =IF(AM12>312,ROUND(AF12*0.1,0),0) -> 0 | AT12: =AS12+AF12 -> 1661.0172 | AU12: =J12-AT12 -> 202.98281 | AW12: =IF(AF12*1.15>J12,ROUND(AF12*0.15,0),0) -> 249 | AX12: =AF12+AW12 -> 1910.0172 | AY12: =J12-AX12 -> -46.017187 | BA12: =IF(AF12*1.2>J12,ROUND(AF12*0.2,0),0) -> 332 | BB12: =AF12+BA12 -> 1993.0172 | BC12: =J12-BB12 -> -129.01719
A13: 강원특별자치도 인제군 | B13: 인제군 | C13: 군 | D13: 군지역 | E13: 군지역 | F13: 10부 | G13: 32097 | H13: 3 | I13: 41 | J13: 44 | K13: =기초자료!AV13/기초자료!I13 -> 0.6672043 | L13: =기초자료!AW13/기초자료!J13 -> 0.94611116 | M13: =기초자료!AX13/기초자료!K13 -> 0.92709478 | N13: =VLOOKUP(E13,'목표실차율, 안정적가동률'!$A$3:$C$9,3,FALSE) -> 0.46 | O13: =기초자료!CI13 -> 0.37597866 | P13: =기초자료!CJ13 -> 0.40613977 | Q13: =기초자료!CK13 -> 0.40465981 | R13: =VLOOKUP(E13,'목표실차율, 안정적가동률'!$F$3:$G$9,2,FALSE) -> 0.25 | S13: =기초자료!DV13 -> 0.25808914 | T13: =기초자료!DW13 -> 0.21670851 | U13: =기초자료!DX13 -> 0.21873899 | V13: =VLOOKUP(F13,'목표실차율, 안정적가동률'!$J$3:$L$6,3,FALSE) -> 0.88 | W13: =기초자료!FI13 -> 0.70581708 | X13: =기초자료!FJ13 -> 0.75538915 | Y13: =기초자료!FK13 -> 0.75295672 | Z13: =VLOOKUP(F13,'목표실차율, 안정적가동률'!$J$3:$L$6,3,FALSE) -> 0.88 | AA13: =기초자료!GP13 -> #DIV/0! | AB13: =기초자료!GQ13 -> #DIV/0! | AC13: =기초자료!GR13 -> 0 | AD13: =ROUND(J13*(Q13/N13)*(Y13/V13),0) -> 33 | AE13: =ROUND(J13*(Q13/N13*0.8+U13/R13*0.2)*(Y13/V13),0) -> 33 | AF13: =AD13 -> 33 | AG13: =VLOOKUP(B13,'[1]Jan-Dec'!$B$2:$AY$61,50,0) -> #N/A | AH13: =ROUND(J13*(Q13/N13*0.8+U13/R13*0.2)*(AC13/Z13),0) -> 0 | AJ13: =J13-AD13 -> 11 | AK13: =J13-AF13 -> 11 | AM13: =ROUND(G13/J13,0) -> 729 | AO13: =IF(AM13>312,ROUND(AD13*0.1,0),0) -> 3 | AP13: =AD13+AO13 -> 36 | AQ13: =J13-AP13 -> 8 | AS13: =IF(AM13>312,ROUND(AF13*0.1,0),0) -> 3 | AT13: =AS13+AF13 -> 36 | AU13: =J13-AT13 -> 8 | AW13: =IF(AF13*1.15>J13,ROUND(AF13*0.15,0),0) -> 0 | AX13: =AF13+AW13 -> 33 | AY13: =J13-AX13 -> 11 | BA13: =IF(AF13*1.2>J13,ROUND(AF13*0.2,0),0) -> 0 | BB13: =AF13+BA13 -> 33 | BC13: =J13-BB13 -> 11
A14: 강원특별자치도 정선군 | B14: 정선군 | C14: 군 | D14: 군지역 | E14: 군지역 | F14: 10부 | G14: 34465 | H14: 86 | I14: 108 | J14: 194 | K14: =기초자료!AV14/기초자료!I14 -> 0.90511752 | L14: =기초자료!AW14/기초자료!J14 -> 0.8821963 | M14: =기초자료!AX14/기초자료!K14 -> 0.89235725 | N14: =VLOOKUP(E14,'목표실차율, 안정적가동률'!$A$3:$C$9,3,FALSE) -> 0.46 | O14: =기초자료!CI14 -> 0.34876279 | P14: =기초자료!CJ14 -> 0.30640266 | Q14: =기초자료!CK14 -> 0.32544938 | R14: =VLOOKUP(E14,'목표실차율, 안정적가동률'!$F$3:$G$9,2,FALSE) -> 0.25 | S14: =기초자료!DV14 -> 0.20752757 | T14: =기초자료!DW14 -> 0.20405268 | U14: =기초자료!DX14 -> 0.20561512 | V14: =VLOOKUP(F14,'목표실차율, 안정적가동률'!$J$3:$L$6,3,FALSE) -> 0.88 | W14: =기초자료!FI14 -> 0.86390413 | X14: =기초자료!FJ14 -> 0.74012933 | Y14: =기초자료!FK14 -> 0.79578317 | Z14: =VLOOKUP(F14,'목표실차율, 안정적가동률'!$J$3:$L$6,3,FALSE) -> 0.88 | AA14: =기초자료!GP14 -> #DIV/0! | AB14: =기초자료!GQ14 -> #DIV/0! | AC14: =기초자료!GR14 -> 0 | AD14: =ROUND(J14*(Q14/N14)*(Y14/V14),0) -> 124 | AE14: =ROUND(J14*(Q14/N14*0.8+U14/R14*0.2)*(Y14/V14),0) -> 128 | AF14: =AE14 -> 128 | AG14: =VLOOKUP(B14,'[1]Jan-Dec'!$B$2:$AY$61,50,0) -> #N/A | AH14: =ROUND(J14*(Q14/N14*0.8+U14/R14*0.2)*(AC14/Z14),0) -> 0 | AJ14: =J14-AD14 -> 70 | AK14: =J14-AF14 -> 66 | AM14: =ROUND(G14/J14,0) -> 178 | AO14: =IF(AM14>312,ROUND(AD14*0.1,0),0) -> 0 | AP14: =AD14+AO14 -> 124 | AQ14: =J14-AP14 -> 70 | AS14: =IF(AM14>312,ROUND(AF14*0.1,0),0) -> 0 | AT14: =AS14+AF14 -> 128 | AU14: =J14-AT14 -> 66 | AW14: =IF(AF14*1.15>J14,ROUND(AF14*0.15,0),0) -> 0 | AX14: =AF14+AW14 -> 128 | AY14: =J14-AX14 -> 66 | BA14: =IF(AF14*1.2>J14,ROUND(AF14*0.2,0),0) -> 0 | BB14: =AF14+BA14 -> 128 | BC14: =J14-BB14 -> 66
A15: 강원특별자치도 철원군 | B15: 철원군 | C15: 군 | D15: 군지역 | E15: 군지역 | F15: 10부 | G15: 41507 | H15: 31 | I15: 72 | J15: 103 | K15: =기초자료!AV15/기초자료!I15 -> 0.87601716 | L15: =기초자료!AW15/기초자료!J15 -> 0.91905045 | M15: =기초자료!AX15/기초자료!K15 -> 0.90609868 | N15: =VLOOKUP(E15,'목표실차율, 안정적가동률'!$A$3:$C$9,3,FALSE) -> 0.46 | O15: =기초자료!CI15 -> 0.4116457 | P15: =기초자료!CJ15 -> 0.41224052 | Q15: =기초자료!CK15 -> 0.41206744 | R15: =VLOOKUP(E15,'목표실차율, 안정적가동률'!$F$3:$G$9,2,FALSE) -> 0.25 | S15: =기초자료!DV15 -> 0.22934785 | T15: =기초자료!DW15 -> 0.22298995 | U15: =기초자료!DX15 -> 0.22483996 | V15: =VLOOKUP(F15,'목표실차율, 안정적가동률'!$J$3:$L$6,3,FALSE) -> 0.88 | W15: =기초자료!FI15 -> 0.6877041 | X15: =기초자료!FJ15 -> 0.71996706 | Y15: =기초자료!FK15 -> 0.71057921 | Z15: =VLOOKUP(F15,'목표실차율, 안정적가동률'!$J$3:$L$6,3,FALSE) -> 0.88 | AA15: =기초자료!GP15 -> #DIV/0! | AB15: =기초자료!GQ15 -> #DIV/0! | AC15: =기초자료!GR15 -> 0 | AD15: =ROUND(J15*(Q15/N15)*(Y15/V15),0) -> 75 | AE15: =ROUND(J15*(Q15/N15*0.8+U15/R15*0.2)*(Y15/V15),0) -> 75 | AF15: =AE15 -> 75 | AG15: =VLOOKUP(B15,'[1]Jan-Dec'!$B$2:$AY$61,50,0) -> #N/A | AH15: =ROUND(J15*(Q15/N15*0.8+U15/R15*0.2)*(AC15/Z15),0) -> 0 | AJ15: =J15-AD15 -> 28 | AK15: =J15-AF15 -> 28 | AM15: =ROUND(G15/J15,0) -> 403 | AO15: =IF(AM15>312,ROUND(AD15*0.1,0),0) -> 8 | AP15: =AD15+AO15 -> 83 | AQ15: =J15-AP15 -> 20 | AS15: =IF(AM15>312,ROUND(AF15*0.1,0),0) -> 8 | AT15: =AS15+AF15 -> 83 | AU15: =J15-AT15 -> 20 | AW15: =IF(AF15*1.15>J15,ROUND(AF15*0.15,0),0) -> 0 | AX15: =AF15+AW15 -> 75 | AY15: =J15-AX15 -> 28 | BA15: =IF(AF15*1.2>J15,ROUND(AF15*0.2,0),0) -> 0 | BB15: =AF15+BA15 -> 75 | BC15: =J15-BB15 -> 28
A16: 강원특별자치도 춘천시 | B16: 춘천시 | C16: 시 | D16: 20~50만 이하 | E16: 50만 이하 | F16: 10부 | G16: 286906 | H16: 662 | I16: 1031 | J16: 1693 | K16: =기초자료!AV16/기초자료!I16 -> 0.8621944 | L16: =기초자료!AW16/기초자료!J16 -> 0.86321803 | M16: =기초자료!AX16/기초자료!K16 -> 0.86284061 | N16: =VLOOKUP(E16,'목표실차율, 안정적가동률'!$A$3:$C$9,3,FALSE) -> 0.49 | O16: =기초자료!CI16 -> 0.46286298 | P16: =기초자료!CJ16 -> 0.45390403 | Q16: =기초자료!CK16 -> 0.45720483 | R16: =VLOOKUP(E16,'목표실차율, 안정적가동률'!$F$3:$G$9,2,FALSE) -> 0.34 | S16: =기초자료!DV16 -> 0.3453081 | T16: =기초자료!DW16 -> 0.35436947 | U16: =기초자료!DX16 -> 0.35103094 | V16: =VLOOKUP(F16,'목표실차율, 안정적가동률'!$J$3:$L$6,3,FALSE) -> 0.88 | W16: =기초자료!FI16 -> 0.7501382 | X16: =기초자료!FJ16 -> 0.73420037 | Y16: =기초자료!FK16 -> 0.74007243 | Z16: =VLOOKUP(F16,'목표실차율, 안정적가동률'!$J$3:$L$6,3,FALSE) -> 0.88 | AA16: =기초자료!GP16 -> #DIV/0! | AB16: =기초자료!GQ16 -> #DIV/0! | AC16: =기초자료!GR16 -> 0 | AD16: =ROUND(J16*(Q16/N16)*(Y16/V16),0) -> 1329 | AE16: =ROUND(J16*(Q16/N16*0.8+U16/R16*0.2)*(Y16/V16),0) -> 1357 | AF16: =AG16 -> 1458.1648 | AG16: =VLOOKUP(B16,'[1]Jan-Dec'!$B$2:$AY$61,50,0) -> 1458.1648 | AH16: =ROUND(J16*(Q16/N16*0.8+U16/R16*0.2)*(AC16/Z16),0) -> 0 | AJ16: =J16-AD16 -> 364 | AK16: =J16-AF16 -> 234.83524 | AM16: =ROUND(G16/J16,0) -> 169 | AO16: =IF(AM16>312,ROUND(AD16*0.1,0),0) -> 0 | AP16: =AD16+AO16 -> 1329 | AQ16: =J16-AP16 -> 364 | AS16: =IF(AM16>312,ROUND(AF16*0.1,0),0) -> 0 | AT16: =AS16+AF16 -> 1458.1648 | AU16: =J16-AT16 -> 234.83524 | AW16: =IF(AF16*1.15>J16,ROUND(AF16*0.15,0),0) -> 0 | AX16: =AF16+AW16 -> 1458.1648 | AY16: =J16-AX16 -> 234.83524 | BA16: =IF(AF16*1.2>J16,ROUND(AF16*0.2,0),0) -> 292 | BB16: =AF16+BA16 -> 1750.1648 | BC16: =J16-BB16 -> -57.164761
A17: 강원특별자치도 태백시 | B17: 태백시 | C17: 시 | D17: 20만 이하 | E17: 20만 이하 | F17: 10부 | G17: 38729 | H17: 104 | I17: 186 | J17: 290 | K17: =기초자료!AV17/기초자료!I17 -> 0.58111339 | L17: =기초자료!AW17/기초자료!J17 -> 0.80705335 | M17: =기초자료!AX17/기초자료!K17 -> 0.72602661 | N17: =VLOOKUP(E17,'목표실차율, 안정적가동률'!$A$3:$C$9,3,FALSE) -> 0.48 | O17: =기초자료!CI17 -> 0.31492533 | P17: =기초자료!CJ17 -> 0.41818936 | Q17: =기초자료!CK17 -> 0.38854837 | R17: =VLOOKUP(E17,'목표실차율, 안정적가동률'!$F$3:$G$9,2,FALSE) -> 0.25 | S17: =기초자료!DV17 -> 0.1971543 | T17: =기초자료!DW17 -> 0.25213534 | U17: =기초자료!DX17 -> 0.23635354 | V17: =VLOOKUP(F17,'목표실차율, 안정적가동률'!$J$3:$L$6,3,FALSE) -> 0.88 | W17: =기초자료!FI17 -> 0.82843941 | X17: =기초자료!FJ17 -> 0.8074256 | Y17: =기초자료!FK17 -> 0.81345742 | Z17: =VLOOKUP(F17,'목표실차율, 안정적가동률'!$J$3:$L$6,3,FALSE) -> 0.88 | AA17: =기초자료!GP17 -> #DIV/0! | AB17: =기초자료!GQ17 -> #DIV/0! | AC17: =기초자료!GR17 -> 0 | AD17: =ROUND(J17*(Q17/N17)*(Y17/V17),0) -> 217 | AE17: =ROUND(J17*(Q17/N17*0.8+U17/R17*0.2)*(Y17/V17),0) -> 224 | AF17: =AE17 -> 224 | AG17: =VLOOKUP(B17,'[1]Jan-Dec'!$B$2:$AY$61,50,0) -> #N/A | AH17: =ROUND(J17*(Q17/N17*0.8+U17/R17*0.2)*(AC17/Z17),0) -> 0 | AJ17: =J17-AD17 -> 73 | AK17: =J17-AF17 -> 66 | AM17: =ROUND(G17/J17,0) -> 134 | AO17: =IF(AM17>312,ROUND(AD17*0.1,0),0) -> 0 | AP17: =AD17+AO17 -> 217 | AQ17: =J17-AP17 -> 73 | AS17: =IF(AM17>312,ROUND(AF17*0.1,0),0) -> 0 | AT17: =AS17+AF17 -> 224 | AU17: =J17-AT17 -> 66 | AW17: =IF(AF17*1.15>J17,ROUND(AF17*0.15,0),0) -> 0 | AX17: =AF17+AW17 -> 224 | AY17: =J17-AX17 -> 66 | BA17: =IF(AF17*1.2>J17,ROUND(AF17*0.2,0),0) -> 0 | BB17: =AF17+BA17 -> 224 | BC17: =J17-BB17 -> 66
A18: 강원특별자치도 평창군 | B18: 평창군 | C18: 군 | D18: 군지역 | E18: 군지역 | F18: 10부 | G18: 40664 | H18: 45 | I18: 59 | J18: 104 | K18: =기초자료!AV18/기초자료!I18 -> 0.79437791 | L18: =기초자료!AW18/기초자료!J18 -> 0.9090627 | M18: =기초자료!AX18/기초자료!K18 -> 0.85943947 | N18: =VLOOKUP(E18,'목표실차율, 안정적가동률'!$A$3:$C$9,3,FALSE) -> 0.46 | O18: =기초자료!CI18 -> 0.32899214 | P18: =기초자료!CJ18 -> 0.34252592 | Q18: =기초자료!CK18 -> 0.33711326 | R18: =VLOOKUP(E18,'목표실차율, 안정적가동률'!$F$3:$G$9,2,FALSE) -> 0.25 | S18: =기초자료!DV18 -> 0.24834561 | T18: =기초자료!DW18 -> 0.28150483 | U18: =기초자료!DX18 -> 0.26824325 | V18: =VLOOKUP(F18,'목표실차율, 안정적가동률'!$J$3:$L$6,3,FALSE) -> 0.88 | W18: =기초자료!FI18 -> 0.63630829 | X18: =기초자료!FJ18 -> 0.60897221 | Y18: =기초자료!FK18 -> 0.61990491 | Z18: =VLOOKUP(F18,'목표실차율, 안정적가동률'!$J$3:$L$6,3,FALSE) -> 0.88 | AA18: =기초자료!GP18 -> #DIV/0! | AB18: =기초자료!GQ18 -> #DIV/0! | AC18: =기초자료!GR18 -> 0 | AD18: =ROUND(J18*(Q18/N18)*(Y18/V18),0) -> 54 | AE18: =ROUND(J18*(Q18/N18*0.8+U18/R18*0.2)*(Y18/V18),0) -> 59 | AF18: =AE18 -> 59 | AG18: =VLOOKUP(B18,'[1]Jan-Dec'!$B$2:$AY$61,50,0) -> #N/A | AH18: =ROUND(J18*(Q18/N18*0.8+U18/R18*0.2)*(AC18/Z18),0) -> 0 | AJ18: =J18-AD18 -> 50 | AK18: =J18-AF18 -> 45 | AM18: =ROUND(G18/J18,0) -> 391 | AO18: =IF(AM18>312,ROUND(AD18*0.1,0),0) -> 5 | AP18: =AD18+AO18 -> 59 | AQ18: =J18-AP18 -> 45 | AS18: =IF(AM18>312,ROUND(AF18*0.1,0),0) -> 6 | AT18: =AS18+AF18 -> 65 | AU18: =J18-AT18 -> 39 | AW18: =IF(AF18*1.15>J18,ROUND(AF18*0.15,0),0) -> 0 | AX18: =AF18+AW18 -> 59 | AY18: =J18-AX18 -> 45 | BA18: =IF(AF18*1.2>J18,ROUND(AF18*0.2,0),0) -> 0 | BB18: =AF18+BA18 -> 59 | BC18: =J18-BB18 -> 45
A19: 강원특별자치도 홍천군 | B19: 홍천군 | C19: 군 | D19: 군지역 | E19: 군지역 | F19: 10부 | G19: 67504 | H19: 72 | I19: 76 | J19: 148 | K19: =기초자료!AV19/기초자료!I19 -> 0.93788233 | L19: =기초자료!AW19/기초자료!J19 -> 0.91930841 | M19: =기초자료!AX19/기초자료!K19 -> 0.92834437 | N19: =VLOOKUP(E19,'목표실차율, 안정적가동률'!$A$3:$C$9,3,FALSE) -> 0.46 | O19: =기초자료!CI19 -> 0.39974821 | P19: =기초자료!CJ19 -> 0.39856148 | Q19: =기초자료!CK19 -> 0.39914474 | R19: =VLOOKUP(E19,'목표실차율, 안정적가동률'!$F$3:$G$9,2,FALSE) -> 0.25 | S19: =기초자료!DV19 -> 0.22820085 | T19: =기초자료!DW19 -> 0.20470273 | U19: =기초자료!DX19 -> 0.2162517 | V19: =VLOOKUP(F19,'목표실차율, 안정적가동률'!$J$3:$L$6,3,FALSE) -> 0.88 | W19: =기초자료!FI19 -> 0.85593742 | X19: =기초자료!FJ19 -> 0.85905585 | Y19: =기초자료!FK19 -> 0.85752319 | Z19: =VLOOKUP(F19,'목표실차율, 안정적가동률'!$J$3:$L$6,3,FALSE) -> 0.88 | AA19: =기초자료!GP19 -> #DIV/0! | AB19: =기초자료!GQ19 -> #DIV/0! | AC19: =기초자료!GR19 -> 0 | AD19: =ROUND(J19*(Q19/N19)*(Y19/V19),0) -> 125 | AE19: =ROUND(J19*(Q19/N19*0.8+U19/R19*0.2)*(Y19/V19),0) -> 125 | AF19: =AE19 -> 125 | AG19: =VLOOKUP(B19,'[1]Jan-Dec'!$B$2:$AY$61,50,0) -> #N/A | AH19: =ROUND(J19*(Q19/N19*0.8+U19/R19*0.2)*(AC19/Z19),0) -> 0 | AJ19: =J19-AD19 -> 23 | AK19: =J19-AF19 -> 23 | AM19: =ROUND(G19/J19,0) -> 456 | AO19: =IF(AM19>312,ROUND(AD19*0.1,0),0) -> 13 | AP19: =AD19+AO19 -> 138 | AQ19: =J19-AP19 -> 10 | AS19: =IF(AM19>312,ROUND(AF19*0.1,0),0) -> 13 | AT19: =AS19+AF19 -> 138 | AU19: =J19-AT19 -> 10 | AW19: =IF(AF19*1.15>J19,ROUND(AF19*0.15,0),0) -> 0 | AX19: =AF19+AW19 -> 125 | AY19: =J19-AX19 -> 23 | BA19: =IF(AF19*1.2>J19,ROUND(AF19*0.2,0),0) -> 25 | BB19: =AF19+BA19 -> 150 | BC19: =J19-BB19 -> -2
A20: 강원특별자치도 화천군 | B20: 화천군 | C20: 군 | D20: 군지역 | E20: 군지역 | F20: 10부 | G20: 23104 | H20: 19 | I20: 35 | J20: 54 | K20: =기초자료!AV20/기초자료!I20 -> 0.71495635 | L20: =기초자료!AW20/기초자료!J20 -> 0.92965959 | M20: =기초자료!AX20/기초자료!K20 -> 0.85411586 | N20: =VLOOKUP(E20,'목표실차율, 안정적가동률'!$A$3:$C$9,3,FALSE) -> 0.46 | O20: =기초자료!CI20 -> 0.3255068 | P20: =기초자료!CJ20 -> 0.41472487 | Q20: =기초자료!CK20 -> 0.38844789 | R20: =VLOOKUP(E20,'목표실차율, 안정적가동률'!$F$3:$G$9,2,FALSE) -> 0.25 | S20: =기초자료!DV20 -> 0.17005303 | T20: =기초자료!DW20 -> 0.22591385 | U20: =기초자료!DX20 -> 0.20946143 | V20: =VLOOKUP(F20,'목표실차율, 안정적가동률'!$J$3:$L$6,3,FALSE) -> 0.88 | W20: =기초자료!FI20 -> 0.83968414 | X20: =기초자료!FJ20 -> 0.75883764 | Y20: =기초자료!FK20 -> 0.78264898 | Z20: =VLOOKUP(F20,'목표실차율, 안정적가동률'!$J$3:$L$6,3,FALSE) -> 0.88 | AA20: =기초자료!GP20 -> #DIV/0! | AB20: =기초자료!GQ20 -> #DIV/0! | AC20: =기초자료!GR20 -> 0 | AD20: =ROUND(J20*(Q20/N20)*(Y20/V20),0) -> 41 | AE20: =ROUND(J20*(Q20/N20*0.8+U20/R20*0.2)*(Y20/V20),0) -> 40 | AF20: =AE20 -> 40 | AG20: =VLOOKUP(B20,'[1]Jan-Dec'!$B$2:$AY$61,50,0) -> #N/A | AH20: =ROUND(J20*(Q20/N20*0.8+U20/R20*0.2)*(AC20/Z20),0) -> 0 | AJ20: =J20-AD20 -> 13 | AK20: =J20-AF20 -> 14 | AM20: =ROUND(G20/J20,0) -> 428 | AO20: =IF(AM20>312,ROUND(AD20*0.1,0),0) -> 4 | AP20: =AD20+AO20 -> 45 | AQ20: =J20-AP20 -> 9 | AS20: =IF(AM20>312,ROUND(AF20*0.1,0),0) -> 4 | AT20: =AS20+AF20 -> 44 | AU20: =J20-AT20 -> 10 | AW20: =IF(AF20*1.15>J20,ROUND(AF20*0.15,0),0) -> 0 | AX20: =AF20+AW20 -> 40 | AY20: =J20-AX20 -> 14 | BA20: =IF(AF20*1.2>J20,ROUND(AF20*0.2,0),0) -> 0 | BB20: =AF20+BA20 -> 40 | BC20: =J20-BB20 -> 14
A21: 강원특별자치도 횡성군 | B21: 횡성군 | C21: 군 | D21: 군지역 | E21: 군지역 | F21: 10부 | G21: 46449 | H21: 37 | I21: 48 | J21: 85 | K21: =기초자료!AV21/기초자료!I21 -> 0.45772447 | L21: =기초자료!AW21/기초자료!J21 -> 0.76057212 | M21: =기초자료!AX21/기초자료!K21 -> 0.62874432 | N21: =VLOOKUP(E21,'목표실차율, 안정적가동률'!$A$3:$C$9,3,FALSE) -> 0.46 | O21: =기초자료!CI21 -> 0.30378063 | P21: =기초자료!CJ21 -> 0.30594534 | Q21: =기초자료!CK21 -> 0.30525936 | R21: =VLOOKUP(E21,'목표실차율, 안정적가동률'!$F$3:$G$9,2,FALSE) -> 0.25 | S21: =기초자료!DV21 -> 0.15275788 | T21: =기초자료!DW21 -> 0.18169043 | U21: =기초자료!DX21 -> 0.17252191 | V21: =VLOOKUP(F21,'목표실차율, 안정적가동률'!$J$3:$L$6,3,FALSE) -> 0.88 | W21: =기초자료!FI21 -> 0.85887913 | X21: =기초자료!FJ21 -> 0.85110936 | Y21: =기초자료!FK21 -> 0.85357155 | Z21: =VLOOKUP(F21,'목표실차율, 안정적가동률'!$J$3:$L$6,3,FALSE) -> 0.88 | AA21: =기초자료!GP21 -> #DIV/0! | AB21: =기초자료!GQ21 -> #DIV/0! | AC21: =기초자료!GR21 -> 0 | AD21: =ROUND(J21*(Q21/N21)*(Y21/V21),0) -> 55 | AE21: =ROUND(J21*(Q21/N21*0.8+U21/R21*0.2)*(Y21/V21),0) -> 55 | AF21: =AE21 -> 55 | AG21: =VLOOKUP(B21,'[1]Jan-Dec'!$B$2:$AY$61,50,0) -> #N/A | AH21: =ROUND(J21*(Q21/N21*0.8+U21/R21*0.2)*(AC21/Z21),0) -> 0 | AJ21: =J21-AD21 -> 30 | AK21: =J21-AF21 -> 30 | AM21: =ROUND(G21/J21,0) -> 546 | AO21: =IF(AM21>312,ROUND(AD21*0.1,0),0) -> 6 | AP21: =AD21+AO21 -> 61 | AQ21: =J21-AP21 -> 24 | AS21: =IF(AM21>312,ROUND(AF21*0.1,0),0) -> 6 | AT21: =AS21+AF21 -> 61 | AU21: =J21-AT21 -> 24 | AW21: =IF(AF21*1.15>J21,ROUND(AF21*0.15,0),0) -> 0 | AX21: =AF21+AW21 -> 55 | AY21: =J21-AX21 -> 30 | BA21: =IF(AF21*1.2>J21,ROUND(AF21*0.2,0),0) -> 0 | BB21: =AF21+BA21 -> 55 | BC21: =J21-BB21 -> 30
A22: 경기도 가평군 | B22: 가평군 | C22: 군 | D22: 군지역 | E22: 군지역 | F22: 10부 | G22: 61976 | H22: 44 | I22: 112 | J22: 156 | K22: =기초자료!AV22/기초자료!I22 -> 0.91456831 | L22: =기초자료!AW22/기초자료!J22 -> 0.9434896 | M22: =기초자료!AX22/기초자료!K22 -> 0.93645469 | N22: =VLOOKUP(E22,'목표실차율, 안정적가동률'!$A$3:$C$9,3,FALSE) -> 0.46 | O22: =기초자료!CI22 -> 0.46135996 | P22: =기초자료!CJ22 -> 0.4405289 | Q22: =기초자료!CK22 -> 0.44547749 | R22: =VLOOKUP(E22,'목표실차율, 안정적가동률'!$F$3:$G$9,2,FALSE) -> 0.25 | S22: =기초자료!DV22 -> 0.32404295 | T22: =기초자료!DW22 -> 0.28359363 | U22: =기초자료!DX22 -> 0.2932027 | V22: =VLOOKUP(F22,'목표실차율, 안정적가동률'!$J$3:$L$6,3,FALSE) -> 0.88 | W22: =기초자료!FI22 -> 0.89853503 | X22: =기초자료!FJ22 -> 0.82614845 | Y22: =기초자료!FK22 -> 0.84334448 | Z22: =VLOOKUP(F22,'목표실차율, 안정적가동률'!$J$3:$L$6,3,FALSE) -> 0.88 | AA22: =기초자료!GP22 -> #DIV/0! | AB22: =기초자료!GQ22 -> #DIV/0! | AC22: =기초자료!GR22 -> 0 | AD22: =ROUND(J22*(Q22/N22)*(Y22/V22),0) -> 145 | AE22: =ROUND(J22*(Q22/N22*0.8+U22/R22*0.2)*(Y22/V22),0) -> 151 | AF22: =AE22 -> 151 | AG22: =VLOOKUP(B22,'[1]Jan-Dec'!$B$2:$AY$61,50,0) -> #N/A | AH22: =ROUND(J22*(Q22/N22*0.8+U22/R22*0.2)*(AC22/Z22),0) -> 0 | AJ22: =J22-AD22 -> 11 | AK22: =J22-AF22 -> 5 | AM22: =ROUND(G22/J22,0) -> 397 | AO22: =IF(AM22>312,ROUND(AD22*0.1,0),0) -> 15 | AP22: =AD22+AO22 -> 160 | AQ22: =J22-AP22 -> -4 | AS22: =IF(AM22>312,ROUND(AF22*0.1,0),0) -> 15 | AT22: =AS22+AF22 -> 166 | AU22: =J22-AT22 -> -10 | AW22: =IF(AF22*1.15>J22,ROUND(AF22*0.15,0),0) -> 23 | AX22: =AF22+AW22 -> 174 | AY22: =J22-AX22 -> -18 | BA22: =IF(AF22*1.2>J22,ROUND(AF22*0.2,0),0) -> 30 | BB22: =AF22+BA22 -> 181 | BC22: =J22-BB22 -> -25
A23: 경기도 고양시 | B23: 고양시 | C23: 시 | D23: 100~500만 이하 | E23: 200만 이하 | F23: 10부 | G23: 1076376 | H23: 717 | I23: 2119 | J23: 2836 | K23: =기초자료!AV23/기초자료!I23 -> 0.89614147 | L23: =기초자료!AW23/기초자료!J23 -> 0.8815282 | M23: =기초자료!AX23/기초자료!K23 -> 0.88441764 | N23: =VLOOKUP(E23,'목표실차율, 안정적가동률'!$A$3:$C$9,3,FALSE) -> 0.51 | O23: =기초자료!CI23 -> 0.72743703 | P23: =기초자료!CJ23 -> 0.52658018 | Q23: =기초자료!CK23 -> 0.56682152 | R23: =VLOOKUP(E23,'목표실차율, 안정적가동률'!$F$3:$G$9,2,FALSE) -> 0.45 | S23: =기초자료!DV23 -> 0.55336966 | T23: =기초자료!DW23 -> 0.35430545 | U23: =기초자료!DX23 -> 0.39418763 | V23: =VLOOKUP(F23,'목표실차율, 안정적가동률'!$J$3:$L$6,3,FALSE) -> 0.88 | W23: =기초자료!FI23 -> 0.77577112 | X23: =기초자료!FJ23 -> 0.77646947 | Y23: =기초자료!FK23 -> 0.77632955 | Z23: =VLOOKUP(F23,'목표실차율, 안정적가동률'!$J$3:$L$6,3,FALSE) -> 0.88 | AA23: =기초자료!GP23 -> #DIV/0! | AB23: =기초자료!GQ23 -> #DIV/0! | AC23: =기초자료!GR23 -> 0 | AD23: =ROUND(J23*(Q23/N23)*(Y23/V23),0) -> 2781 | AE23: =ROUND(J23*(Q23/N23*0.8+U23/R23*0.2)*(Y23/V23),0) -> 2663 | AF23: =AE23 -> 2663 | AG23: =VLOOKUP(B23,'[1]Jan-Dec'!$B$2:$AY$61,50,0) -> #N/A | AH23: =ROUND(J23*(Q23/N23*0.8+U23/R23*0.2)*(AC23/Z23),0) -> 0 | AJ23: =J23-AD23 -> 55 | AK23: =J23-AF23 -> 173 | AM23: =ROUND(G23/J23,0) -> 380 | AO23: =IF(AM23>312,ROUND(AD23*0.1,0),0) -> 278 | AP23: =AD23+AO23 -> 3059 | AQ23: =J23-AP23 -> -223 | AS23: =IF(AM23>312,ROUND(AF23*0.1,0),0) -> 266 | AT23: =AS23+AF23 -> 2929 | AU23: =J23-AT23 -> -93 | AW23: =IF(AF23*1.15>J23,ROUND(AF23*0.15,0),0) -> 399 | AX23: =AF23+AW23 -> 3062 | AY23: =J23-AX23 -> -226 | BA23: =IF(AF23*1.2>J23,ROUND(AF23*0.2,0),0) -> 533 | BB23: =AF23+BA23 -> 3196 | BC23: =J23-BB23 -> -360
A24: 경기도 화성·오산 통합사업구역 | B24: 화성·오산 통합사업구역 | C24: 시 | D24: 100~500만 이하 | E24: 200만 이하 | F24: 10부 | G24: 1166969 | H24: 390 | I24: 1609 | J24: 1999 | K24: =기초자료!AV24/기초자료!I24 -> 0.94245326 | L24: =기초자료!AW24/기초자료!J24 -> 0.91777012 | M24: =기초자료!AX24/기초자료!K24 -> 0.92249585 | N24: =VLOOKUP(E24,'목표실차율, 안정적가동률'!$A$3:$C$9,3,FALSE) -> 0.51 | O24: =기초자료!CI24 -> 0.55048021 | P24: =기초자료!CJ24 -> 0.50222539 | Q24: =기초자료!CK24 -> 0.51166392 | R24: =VLOOKUP(E24,'목표실차율, 안정적가동률'!$F$3:$G$9,2,FALSE) -> 0.45 | S24: =기초자료!DV24 -> 0.39400989 | T24: =기초자료!DW24 -> 0.40179558 | U24: =기초자료!DX24 -> 0.40027272 | V24: =VLOOKUP(F24,'목표실차율, 안정적가동률'!$J$3:$L$6,3,FALSE) -> 0.88 | W24: =기초자료!FI24 -> 0.86560542 | X24: =기초자료!FJ24 -> 0.78599268 | Y24: =기초자료!FK24 -> 0.80156474 | Z24: =VLOOKUP(F24,'목표실차율, 안정적가동률'!$J$3:$L$6,3,FALSE) -> 0.88 | AA24: =기초자료!GP24 -> #DIV/0! | AB24: =기초자료!GQ24 -> #DIV/0! | AC24: =기초자료!GR24 -> 0 | AD24: =ROUND(J24*(Q24/N24)*(Y24/V24),0) -> 1827 | AE24: =ROUND(J24*(Q24/N24*0.8+U24/R24*0.2)*(Y24/V24),0) -> 1785 | AF24: =AG24 -> 2050.0863 | AG24: =VLOOKUP(B24,'[1]Jan-Dec'!$B$2:$AY$61,50,0) -> 2050.0863 | AH24: =ROUND(J24*(Q24/N24*0.8+U24/R24*0.2)*(AC24/Z24),0) -> 0 | AJ24: =J24-AD24 -> 172 | AK24: =J24-AF24 -> -51.086344 | AM24: =ROUND(G24/J24,0) -> 584 | AO24: =IF(AM24>312,ROUND(AD24*0.1,0),0) -> 183 | AP24: =AD24+AO24 -> 2010 | AQ24: =J24-AP24 -> -11 | AS24: =IF(AM24>312,ROUND(AF24*0.1,0),0) -> 205 | AT24: =AS24+AF24 -> 2255.0863 | AU24: =J24-AT24 -> -256.08634 | AW24: =IF(AF24*1.15>J24,ROUND(AF24*0.15,0),0) -> 308 | AX24: =AF24+AW24 -> 2358.0863 | AY24: =J24-AX24 -> -359.08634 | BA24: =IF(AF24*1.2>J24,ROUND(AF24*0.2,0),0) -> 410 | BB24: =AF24+BA24 -> 2460.0863 | BC24: =J24-BB24 -> -461.08634
A25: 경기도 광명시 | B25: 광명시 | C25: 시 | D25: 20~50만 이하 | E25: 50만 이하 | F25: 10부 | G25: 280129 | H25: 415 | I25: 846 | J25: 1261 | K25: =기초자료!AV25/기초자료!I25 -> 0.89687176 | L25: =기초자료!AW25/기초자료!J25 -> 0.85344737 | M25: =기초자료!AX25/기초자료!K25 -> 0.86338885 | N25: =VLOOKUP(E25,'목표실차율, 안정적가동률'!$A$3:$C$9,3,FALSE) -> 0.49 | O25: =기초자료!CI25 -> 0.5183141 | P25: =기초자료!CJ25 -> 0.47249038 | Q25: =기초자료!CK25 -> 0.483388 | R25: =VLOOKUP(E25,'목표실차율, 안정적가동률'!$F$3:$G$9,2,FALSE) -> 0.34 | S25: =기초자료!DV25 -> 0.36393436 | T25: =기초자료!DW25 -> 0.33932829 | U25: =기초자료!DX25 -> 0.34518001 | V25: =VLOOKUP(F25,'목표실차율, 안정적가동률'!$J$3:$L$6,3,FALSE) -> 0.88 | W25: =기초자료!FI25 -> 0.74472164 | X25: =기초자료!FJ25 -> 0.75060722 | Y25: =기초자료!FK25 -> 0.74920753 | Z25: =VLOOKUP(F25,'목표실차율, 안정적가동률'!$J$3:$L$6,3,FALSE) -> 0.88 | AA25: =기초자료!GP25 -> #DIV/0! | AB25: =기초자료!GQ25 -> #DIV/0! | AC25: =기초자료!GR25 -> 0 | AD25: =ROUND(J25*(Q25/N25)*(Y25/V25),0) -> 1059 | AE25: =ROUND(J25*(Q25/N25*0.8+U25/R25*0.2)*(Y25/V25),0) -> 1065 | AF25: =AE25 -> 1065 | AG25: =VLOOKUP(B25,'[1]Jan-Dec'!$B$2:$AY$61,50,0) -> #N/A | AH25: =ROUND(J25*(Q25/N25*0.8+U25/R25*0.2)*(AC25/Z25),0) -> 0 | AJ25: =J25-AD25 -> 202 | AK25: =J25-AF25 -> 196 | AM25: =ROUND(G25/J25,0) -> 222 | AO25: =IF(AM25>312,ROUND(AD25*0.1,0),0) -> 0 | AP25: =AD25+AO25 -> 1059 | AQ25: =J25-AP25 -> 202 | AS25: =IF(AM25>312,ROUND(AF25*0.1,0),0) -> 0 | AT25: =AS25+AF25 -> 1065 | AU25: =J25-AT25 -> 196 | AW25: =IF(AF25*1.15>J25,ROUND(AF25*0.15,0),0) -> 0 | AX25: =AF25+AW25 -> 1065 | AY25: =J25-AX25 -> 196 | BA25: =IF(AF25*1.2>J25,ROUND(AF25*0.2,0),0) -> 213 | BB25: =AF25+BA25 -> 1278 | BC25: =J25-BB25 -> -17
A26: 경기도 김포시 | B26: 김포시 | C26: 시 | D26: 20~50만 이하 | E26: 50만 이하 | F26: 10부 | G26: 485943 | H26: 143 | I26: 486 | J26: 629 | K26: =기초자료!AV26/기초자료!I26 -> 0.98679706 | L26: =기초자료!AW26/기초자료!J26 -> 0.89939011 | M26: =기초자료!AX26/기초자료!K26 -> 0.91898618 | N26: =VLOOKUP(E26,'목표실차율, 안정적가동률'!$A$3:$C$9,3,FALSE) -> 0.49 | O26: =기초자료!CI26 -> 0.6175392 | P26: =기초자료!CJ26 -> 0.48399578 | Q26: =기초자료!CK26 -> 0.51614456 | R26: =VLOOKUP(E26,'목표실차율, 안정적가동률'!$F$3:$G$9,2,FALSE) -> 0.34 | S26: =기초자료!DV26 -> 0.4359704 | T26: =기초자료!DW26 -> 0.3450037 | U26: =기초자료!DX26 -> 0.36690271 | V26: =VLOOKUP(F26,'목표실차율, 안정적가동률'!$J$3:$L$6,3,FALSE) -> 0.88 | W26: =기초자료!FI26 -> 0.87747003 | X26: =기초자료!FJ26 -> 0.75094955 | Y26: =기초자료!FK26 -> 0.78140765 | Z26: =VLOOKUP(F26,'목표실차율, 안정적가동률'!$J$3:$L$6,3,FALSE) -> 0.88 | AA26: =기초자료!GP26 -> #DIV/0! | AB26: =기초자료!GQ26 -> #DIV/0! | AC26: =기초자료!GR26 -> 0 | AD26: =ROUND(J26*(Q26/N26)*(Y26/V26),0) -> 588 | AE26: =ROUND(J26*(Q26/N26*0.8+U26/R26*0.2)*(Y26/V26),0) -> 591 | AF26: =AG26 -> 633.41749 | AG26: =VLOOKUP(B26,'[1]Jan-Dec'!$B$2:$AY$61,50,0) -> 633.41749 | AH26: =ROUND(J26*(Q26/N26*0.8+U26/R26*0.2)*(AC26/Z26),0) -> 0 | AJ26: =J26-AD26 -> 41 | AK26: =J26-AF26 -> -4.4174859 | AM26: =ROUND(G26/J26,0) -> 773 | AO26: =IF(AM26>312,ROUND(AD26*0.1,0),0) -> 59 | AP26: =AD26+AO26 -> 647 | AQ26: =J26-AP26 -> -18 | AS26: =IF(AM26>312,ROUND(AF26*0.1,0),0) -> 63 | AT26: =AS26+AF26 -> 696.41749 | AU26: =J26-AT26 -> -67.417486 | AW26: =IF(AF26*1.15>J26,ROUND(AF26*0.15,0),0) -> 95 | AX26: =AF26+AW26 -> 728.41749 | AY26: =J26-AX26 -> -99.417486 | BA26: =IF(AF26*1.2>J26,ROUND(AF26*0.2,0),0) -> 127 | BB26: =AF26+BA26 -> 760.41749 | BC26: =J26-BB26 -> -131.41749
A27: 경기도 동두천시 | B27: 동두천시 | C27: 시 | D27: 20만 이하 | E27: 20만 이하 | F27: 10부 | G27: 89037 | H27: 199 | I27: 210 | J27: 409 | K27: =기초자료!AV27/기초자료!I27 -> 1.2577377 | L27: =기초자료!AW27/기초자료!J27 -> 0.87163683 | M27: =기초자료!AX27/기초자료!K27 -> 1.0471372 | N27: =VLOOKUP(E27,'목표실차율, 안정적가동률'!$A$3:$C$9,3,FALSE) -> 0.48 | O27: =기초자료!CI27 -> 0.40348022 | P27: =기초자료!CJ27 -> 0.39791524 | Q27: =기초자료!CK27 -> 0.40095352 | R27: =VLOOKUP(E27,'목표실차율, 안정적가동률'!$F$3:$G$9,2,FALSE) -> 0.25 | S27: =기초자료!DV27 -> 0.22975019 | T27: =기초자료!DW27 -> 0.24898556 | U27: =기초자료!DX27 -> 0.23848375 | V27: =VLOOKUP(F27,'목표실차율, 안정적가동률'!$J$3:$L$6,3,FALSE) -> 0.88 | W27: =기초자료!FI27 -> 0.84752918 | X27: =기초자료!FJ27 -> 0.75462525 | Y27: =기초자료!FK27 -> 0.80534743 | Z27: =VLOOKUP(F27,'목표실차율, 안정적가동률'!$J$3:$L$6,3,FALSE) -> 0.88 | AA27: =기초자료!GP27 -> #DIV/0! | AB27: =기초자료!GQ27 -> #DIV/0! | AC27: =기초자료!GR27 -> 0 | AD27: =ROUND(J27*(Q27/N27)*(Y27/V27),0) -> 313 | AE27: =ROUND(J27*(Q27/N27*0.8+U27/R27*0.2)*(Y27/V27),0) -> 322 | AF27: =AE27 -> 322 | AG27: =VLOOKUP(B27,'[1]Jan-Dec'!$B$2:$AY$61,50,0) -> #N/A | AH27: =ROUND(J27*(Q27/N27*0.8+U27/R27*0.2)*(AC27/Z27),0) -> 0 | AJ27: =J27-AD27 -> 96 | AK27: =J27-AF27 -> 87 | AM27: =ROUND(G27/J27,0) -> 218 | AO27: =IF(AM27>312,ROUND(AD27*0.1,0),0) -> 0 | AP27: =AD27+AO27 -> 313 | AQ27: =J27-AP27 -> 96 | AS27: =IF(AM27>312,ROUND(AF27*0.1,0),0) -> 0 | AT27: =AS27+AF27 -> 322 | AU27: =J27-AT27 -> 87 | AW27: =IF(AF27*1.15>J27,ROUND(AF27*0.15,0),0) -> 0 | AX27: =AF27+AW27 -> 322 | AY27: =J27-AX27 -> 87 | BA27: =IF(AF27*1.2>J27,ROUND(AF27*0.2,0),0) -> 0 | BB27: =AF27+BA27 -> 322 | BC27: =J27-BB27 -> 87
A28: 경기도 부천시 | B28: 부천시 | C28: 시 | D28: 50~100만 이하 | E28: 100만 이하 | F28: 10부 | G28: 784273 | H28: 980 | I28: 2483 | J28: 3463 | K28: =기초자료!AV28/기초자료!I28 -> 0.8704597 | L28: =기초자료!AW28/기초자료!J28 -> 0.85431943 | M28: =기초자료!AX28/기초자료!K28 -> 0.85712059 | N28: =VLOOKUP(E28,'목표실차율, 안정적가동률'!$A$3:$C$9,3,FALSE) -> 0.5 | O28: =기초자료!CI28 -> 0.49222996 | P28: =기초자료!CJ28 -> 0.41101602 | Q28: =기초자료!CK28 -> 0.42533013 | R28: =VLOOKUP(E28,'목표실차율, 안정적가동률'!$F$3:$G$9,2,FALSE) -> 0.38 | S28: =기초자료!DV28 -> 0.36730792 | T28: =기초자료!DW28 -> 0.32412204 | U28: =기초자료!DX28 -> 0.33173363 | V28: =VLOOKUP(F28,'목표실차율, 안정적가동률'!$J$3:$L$6,3,FALSE) -> 0.88 | W28: =기초자료!FI28 -> 0.84288658 | X28: =기초자료!FJ28 -> 0.75668438 | Y28: =기초자료!FK28 -> 0.77187768 | Z28: =VLOOKUP(F28,'목표실차율, 안정적가동률'!$J$3:$L$6,3,FALSE) -> 0.88 | AA28: =기초자료!GP28 -> #DIV/0! | AB28: =기초자료!GQ28 -> #DIV/0! | AC28: =기초자료!GR28 -> 0 | AD28: =ROUND(J28*(Q28/N28)*(Y28/V28),0) -> 2584 | AE28: =ROUND(J28*(Q28/N28*0.8+U28/R28*0.2)*(Y28/V28),0) -> 2597 | AF28: =AE28 -> 2597 | AG28: =VLOOKUP(B28,'[1]Jan-Dec'!$B$2:$AY$61,50,0) -> #N/A | AH28: =ROUND(J28*(Q28/N28*0.8+U28/R28*0.2)*(AC28/Z28),0) -> 0 | AJ28: =J28-AD28 -> 879 | AK28: =J28-AF28 -> 866 | AM28: =ROUND(G28/J28,0) -> 226 | AO28: =IF(AM28>312,ROUND(AD28*0.1,0),0) -> 0 | AP28: =AD28+AO28 -> 2584 | AQ28: =J28-AP28 -> 879 | AS28: =IF(AM28>312,ROUND(AF28*0.1,0),0) -> 0 | AT28: =AS28+AF28 -> 2597 | AU28: =J28-AT28 -> 866 | AW28: =IF(AF28*1.15>J28,ROUND(AF28*0.15,0),0) -> 0 | AX28: =AF28+AW28 -> 2597 | AY28: =J28-AX28 -> 866 | BA28: =IF(AF28*1.2>J28,ROUND(AF28*0.2,0),0) -> 0 | BB28: =AF28+BA28 -> 2597 | BC28: =J28-BB28 -> 866
A29: 경기도 남양주·구리 통합사업구역 | B29: 남양주·구리 통합사업구역 | C29: 시 | D29: 50~100만 이하 | E29: 100만 이하 | F29: 10부 | G29: 920212 | H29: 606 | I29: 1550 | J29: 2156 | K29: =기초자료!AV29/기초자료!I29 -> 0.86411232 | L29: =기초자료!AW29/기초자료!J29 -> 0.89385944 | M29: =기초자료!AX29/기초자료!K29 -> 0.88740119 | N29: =VLOOKUP(E29,'목표실차율, 안정적가동률'!$A$3:$C$9,3,FALSE) -> 0.5 | O29: =기초자료!CI29 -> 0.58051396 | P29: =기초자료!CJ29 -> 0.4356147 | Q29: =기초자료!CK29 -> 0.4662475 | R29: =VLOOKUP(E29,'목표실차율, 안정적가동률'!$F$3:$G$9,2,FALSE) -> 0.38 | S29: =기초자료!DV29 -> 0.41728593 | T29: =기초자료!DW29 -> 0.29794721 | U29: =기초자료!DX29 -> 0.32317632 | V29: =VLOOKUP(F29,'목표실차율, 안정적가동률'!$J$3:$L$6,3,FALSE) -> 0.88 | W29: =기초자료!FI29 -> 0.88241223 | X29: =기초자료!FJ29 -> 0.77646437 | Y29: =기초자료!FK29 -> 0.79886255 | Z29: =VLOOKUP(F29,'목표실차율, 안정적가동률'!$J$3:$L$6,3,FALSE) -> 0.88 | AA29: =기초자료!GP29 -> #DIV/0! | AB29: =기초자료!GQ29 -> #DIV/0! | AC29: =기초자료!GR29 -> 0 | AD29: =ROUND(J29*(Q29/N29)*(Y29/V29),0) -> 1825 | AE29: =ROUND(J29*(Q29/N29*0.8+U29/R29*0.2)*(Y29/V29),0) -> 1793 | AF29: =AG29 -> 2027.4016 | AG29: =VLOOKUP(B29,'[1]Jan-Dec'!$B$2:$AY$61,50,0) -> 2027.4016 | AH29: =ROUND(J29*(Q29/N29*0.8+U29/R29*0.2)*(AC29/Z29),0) -> 0 | AJ29: =J29-AD29 -> 331 | AK29: =J29-AF29 -> 128.59835 | AM29: =ROUND(G29/J29,0) -> 427 | AO29: =IF(AM29>312,ROUND(AD29*0.1,0),0) -> 183 | AP29: =AD29+AO29 -> 2008 | AQ29: =J29-AP29 -> 148 | AS29: =IF(AM29>312,ROUND(AF29*0.1,0),0) -> 203 | AT29: =AS29+AF29 -> 2230.4016 | AU29: =J29-AT29 -> -74.401649 | AW29: =IF(AF29*1.15>J29,ROUND(AF29*0.15,0),0) -> 304 | AX29: =AF29+AW29 -> 2331.4016 | AY29: =J29-AX29 -> -175.40165 | BA29: =IF(AF29*1.2>J29,ROUND(AF29*0.2,0),0) -> 405 | BB29: =AF29+BA29 -> 2432.4016 | BC29: =J29-BB29 -> -276.40165
A30: 경기도 성남시 | B30: 성남시 | C30: 시 | D30: 50~100만 이하 | E30: 100만 이하 | F30: 10부 | G30: 917374 | H30: 1085 | I30: 2512 | J30: 3597 | K30: =기초자료!AV30/기초자료!I30 -> 0.97851791 | L30: =기초자료!AW30/기초자료!J30 -> 0.78826484 | M30: =기초자료!AX30/기초자료!K30 -> 0.83540064 | N30: =VLOOKUP(E30,'목표실차율, 안정적가동률'!$A$3:$C$9,3,FALSE) -> 0.5 | O30: =기초자료!CI30 -> 0.49143178 | P30: =기초자료!CJ30 -> 0.35396948 | Q30: =기초자료!CK30 -> 0.39386065 | R30: =VLOOKUP(E30,'목표실차율, 안정적가동률'!$F$3:$G$9,2,FALSE) -> 0.38 | S30: =기초자료!DV30 -> 0.34889921 | T30: =기초자료!DW30 -> 0.26777093 | U30: =기초자료!DX30 -> 0.29131412 | V30: =VLOOKUP(F30,'목표실차율, 안정적가동률'!$J$3:$L$6,3,FALSE) -> 0.88 | W30: =기초자료!FI30 -> 0.84200889 | X30: =기초자료!FJ30 -> 0.74082748 | Y30: =기초자료!FK30 -> 0.77019004 | Z30: =VLOOKUP(F30,'목표실차율, 안정적가동률'!$J$3:$L$6,3,FALSE) -> 0.88 | AA30: =기초자료!GP30 -> #DIV/0! | AB30: =기초자료!GQ30 -> #DIV/0! | AC30: =기초자료!GR30 -> 0 | AD30: =ROUND(J30*(Q30/N30)*(Y30/V30),0) -> 2480 | AE30: =ROUND(J30*(Q30/N30*0.8+U30/R30*0.2)*(Y30/V30),0) -> 2467 | AF30: =AE30 -> 2467 | AG30: =VLOOKUP(B30,'[1]Jan-Dec'!$B$2:$AY$61,50,0) -> #N/A | AH30: =ROUND(J30*(Q30/N30*0.8+U30/R30*0.2)*(AC30/Z30),0) -> 0 | AJ30: =J30-AD30 -> 1117 | AK30: =J30-AF30 -> 1130 | AM30: =ROUND(G30/J30,0) -> 255 | AO30: =IF(AM30>312,ROUND(AD30*0.1,0),0) -> 0 | AP30: =AD30+AO30 -> 2480 | AQ30: =J30-AP30 -> 1117 | AS30: =IF(AM30>312,ROUND(AF30*0.1,0),0) -> 0 | AT30: =AS30+AF30 -> 2467 | AU30: =J30-AT30 -> 1130 | AW30: =IF(AF30*1.15>J30,ROUND(AF30*0.15,0),0) -> 0 | AX30: =AF30+AW30 -> 2467 | AY30: =J30-AX30 -> 1130 | BA30: =IF(AF30*1.2>J30,ROUND(AF30*0.2,0),0) -> 0 | BB30: =AF30+BA30 -> 2467 | BC30: =J30-BB30 -> 1130
A31: 경기도 수원시 | B31: 수원시 | C31: 시 | D31: 100~500만 이하 | E31: 200만 이하 | F31: 10부 | G31: 1195718 | H31: 1570 | I31: 3129 | J31: 4699 | K31: =기초자료!AV31/기초자료!I31 -> 0.90242947 | L31: =기초자료!AW31/기초자료!J31 -> 0.87015606 | M31: =기초자료!AX31/기초자료!K31 -> 0.87905314 | N31: =VLOOKUP(E31,'목표실차율, 안정적가동률'!$A$3:$C$9,3,FALSE) -> 0.51 | O31: =기초자료!CI31 -> 0.57949047 | P31: =기초자료!CJ31 -> 0.53675968 | Q31: =기초자료!CK31 -> 0.54885288 | R31: =VLOOKUP(E31,'목표실차율, 안정적가동률'!$F$3:$G$9,2,FALSE) -> 0.45 | S31: =기초자료!DV31 -> 0.41911937 | T31: =기초자료!DW31 -> 0.42791464 | U31: =기초자료!DX31 -> 0.4254255 | V31: =VLOOKUP(F31,'목표실차율, 안정적가동률'!$J$3:$L$6,3,FALSE) -> 0.88 | W31: =기초자료!FI31 -> 0.85722987 | X31: =기초자료!FJ31 -> 0.75554997 | Y31: =기초자료!FK31 -> 0.78432632 | Z31: =VLOOKUP(F31,'목표실차율, 안정적가동률'!$J$3:$L$6,3,FALSE) -> 0.88 | AA31: =기초자료!GP31 -> #DIV/0! | AB31: =기초자료!GQ31 -> #DIV/0! | AC31: =기초자료!GR31 -> 0 | AD31: =ROUND(J31*(Q31/N31)*(Y31/V31),0) -> 4507 | AE31: =ROUND(J31*(Q31/N31*0.8+U31/R31*0.2)*(Y31/V31),0) -> 4398 | AF31: =AE31 -> 4398 | AG31: =VLOOKUP(B31,'[1]Jan-Dec'!$B$2:$AY$61,50,0) -> #N/A | AH31: =ROUND(J31*(Q31/N31*0.8+U31/R31*0.2)*(AC31/Z31),0) -> 0 | AJ31: =J31-AD31 -> 192 | AK31: =J31-AF31 -> 301 | AM31: =ROUND(G31/J31,0) -> 254 | AO31: =IF(AM31>312,ROUND(AD31*0.1,0),0) -> 0 | AP31: =AD31+AO31 -> 4507 | AQ31: =J31-AP31 -> 192 | AS31: =IF(AM31>312,ROUND(AF31*0.1,0),0) -> 0 | AT31: =AS31+AF31 -> 4398 | AU31: =J31-AT31 -> 301 | AW31: =IF(AF31*1.15>J31,ROUND(AF31*0.15,0),0) -> 660 | AX31: =AF31+AW31 -> 5058 | AY31: =J31-AX31 -> -359 | BA31: =IF(AF31*1.2>J31,ROUND(AF31*0.2,0),0) -> 880 | BB31: =AF31+BA31 -> 5278 | BC31: =J31-BB31 -> -579
A32: 경기도 시흥시 | B32: 시흥시 | C32: 시 | D32: 50~100만 이하 | E32: 100만 이하 | F32: 10부 | G32: 518174 | H32: 275 | I32: 1090 | J32: 1365 | K32: =기초자료!AV32/기초자료!I32 -> 0.95286388 | L32: =기초자료!AW32/기초자료!J32 -> 0.87347098 | M32: =기초자료!AX32/기초자료!K32 -> 0.88853436 | N32: =VLOOKUP(E32,'목표실차율, 안정적가동률'!$A$3:$C$9,3,FALSE) -> 0.5 | O32: =기초자료!CI32 -> 0.55021027 | P32: =기초자료!CJ32 -> 0.49700769 | Q32: =기초자료!CK32 -> 0.50783275 | R32: =VLOOKUP(E32,'목표실차율, 안정적가동률'!$F$3:$G$9,2,FALSE) -> 0.38 | S32: =기초자료!DV32 -> 0.39636569 | T32: =기초자료!DW32 -> 0.34669526 | U32: =기초자료!DX32 -> 0.35680163 | V32: =VLOOKUP(F32,'목표실차율, 안정적가동률'!$J$3:$L$6,3,FALSE) -> 0.88 | W32: =기초자료!FI32 -> 0.83695921 | X32: =기초자료!FJ32 -> 0.780138 | Y32: =기초자료!FK32 -> 0.79169933 | Z32: =VLOOKUP(F32,'목표실차율, 안정적가동률'!$J$3:$L$6,3,FALSE) -> 0.88 | AA32: =기초자료!GP32 -> #DIV/0! | AB32: =기초자료!GQ32 -> #DIV/0! | AC32: =기초자료!GR32 -> 0 | AD32: =ROUND(J32*(Q32/N32)*(Y32/V32),0) -> 1247 | AE32: =ROUND(J32*(Q32/N32*0.8+U32/R32*0.2)*(Y32/V32),0) -> 1228 | AF32: =AE32 -> 1228 | AG32: =VLOOKUP(B32,'[1]Jan-Dec'!$B$2:$AY$61,50,0) -> #N/A | AH32: =ROUND(J32*(Q32/N32*0.8+U32/R32*0.2)*(AC32/Z32),0) -> 0 | AJ32: =J32-AD32 -> 118 | AK32: =J32-AF32 -> 137 | AM32: =ROUND(G32/J32,0) -> 380 | AO32: =IF(AM32>312,ROUND(AD32*0.1,0),0) -> 125 | AP32: =AD32+AO32 -> 1372 | AQ32: =J32-AP32 -> -7 | AS32: =IF(AM32>312,ROUND(AF32*0.1,0),0) -> 123 | AT32: =AS32+AF32 -> 1351 | AU32: =J32-AT32 -> 14 | AW32: =IF(AF32*1.15>J32,ROUND(AF32*0.15,0),0) -> 184 | AX32: =AF32+AW32 -> 1412 | AY32: =J32-AX32 -> -47 | BA32: =IF(AF32*1.2>J32,ROUND(AF32*0.2,0),0) -> 246 | BB32: =AF32+BA32 -> 1474 | BC32: =J32-BB32 -> -109
A33: 경기도 안산시 | B33: 안산시 | C33: 시 | D33: 50~100만 이하 | E33: 100만 이하 | F33: 10부 | G33: 633417 | H33: 525 | I33: 2085 | J33: 2610 | K33: =기초자료!AV33/기초자료!I33 -> 0.95584613 | L33: =기초자료!AW33/기초자료!J33 -> 0.88222819 | M33: =기초자료!AX33/기초자료!K33 -> 0.89528803 | N33: =VLOOKUP(E33,'목표실차율, 안정적가동률'!$A$3:$C$9,3,FALSE) -> 0.5 | O33: =기초자료!CI33 -> 0.55859556 | P33: =기초자료!CJ33 -> 0.49133162 | Q33: =기초자료!CK33 -> 0.50407139 | R33: =VLOOKUP(E33,'목표실차율, 안정적가동률'!$F$3:$G$9,2,FALSE) -> 0.38 | S33: =기초자료!DV33 -> 0.43765726 | T33: =기초자료!DW33 -> 0.3771846 | U33: =기초자료!DX33 -> 0.3886381 | V33: =VLOOKUP(F33,'목표실차율, 안정적가동률'!$J$3:$L$6,3,FALSE) -> 0.88 | W33: =기초자료!FI33 -> 0.83957922 | X33: =기초자료!FJ33 -> 0.78546619 | Y33: =기초자료!FK33 -> 0.79571518 | Z33: =VLOOKUP(F33,'목표실차율, 안정적가동률'!$J$3:$L$6,3,FALSE) -> 0.88 | AA33: =기초자료!GP33 -> #DIV/0! | AB33: =기초자료!GQ33 -> #DIV/0! | AC33: =기초자료!GR33 -> 0 | AD33: =ROUND(J33*(Q33/N33)*(Y33/V33),0) -> 2379 | AE33: =ROUND(J33*(Q33/N33*0.8+U33/R33*0.2)*(Y33/V33),0) -> 2386 | AF33: =AE33 -> 2386 | AG33: =VLOOKUP(B33,'[1]Jan-Dec'!$B$2:$AY$61,50,0) -> #N/A | AH33: =ROUND(J33*(Q33/N33*0.8+U33/R33*0.2)*(AC33/Z33),0) -> 0 | AJ33: =J33-AD33 -> 231 | AK33: =J33-AF33 -> 224 | AM33: =ROUND(G33/J33,0) -> 243 | AO33: =IF(AM33>312,ROUND(AD33*0.1,0),0) -> 0 | AP33: =AD33+AO33 -> 2379 | AQ33: =J33-AP33 -> 231 | AS33: =IF(AM33>312,ROUND(AF33*0.1,0),0) -> 0 | AT33: =AS33+AF33 -> 2386 | AU33: =J33-AT33 -> 224 | AW33: =IF(AF33*1.15>J33,ROUND(AF33*0.15,0),0) -> 358 | AX33: =AF33+AW33 -> 2744 | AY33: =J33-AX33 -> -134 | BA33: =IF(AF33*1.2>J33,ROUND(AF33*0.2,0),0) -> 477 | BB33: =AF33+BA33 -> 2863 | BC33: =J33-BB33 -> -253
A34: 경기도 안성시 | B34: 안성시 | C34: 시 | D34: 20만 이하 | E34: 20만 이하 | F34: 10부 | G34: 189456 | H34: 112 | I34: 291 | J34: 403 | K34: =기초자료!AV34/기초자료!I34 -> 0.89903102 | L34: =기초자료!AW34/기초자료!J34 -> 0.93643934 | M34: =기초자료!AX34/기초자료!K34 -> 0.92737951 | N34: =VLOOKUP(E34,'목표실차율, 안정적가동률'!$A$3:$C$9,3,FALSE) -> 0.48 | O34: =기초자료!CI34 -> 0.45683507 | P34: =기초자료!CJ34 -> 0.42458525 | Q34: =기초자료!CK34 -> 0.432157 | R34: =VLOOKUP(E34,'목표실차율, 안정적가동률'!$F$3:$G$9,2,FALSE) -> 0.25 | S34: =기초자료!DV34 -> 0.29200493 | T34: =기초자료!DW34 -> 0.30637707 | U34: =기초자료!DX34 -> 0.30300272 | V34: =VLOOKUP(F34,'목표실차율, 안정적가동률'!$J$3:$L$6,3,FALSE) -> 0.88 | W34: =기초자료!FI34 -> 0.83828225 | X34: =기초자료!FJ34 -> 0.77815937 | Y34: =기초자료!FK34 -> 0.79227527 | Z34: =VLOOKUP(F34,'목표실차율, 안정적가동률'!$J$3:$L$6,3,FALSE) -> 0.88 | AA34: =기초자료!GP34 -> #DIV/0! | AB34: =기초자료!GQ34 -> #DIV/0! | AC34: =기초자료!GR34 -> 0 | AD34: =ROUND(J34*(Q34/N34)*(Y34/V34),0) -> 327 | AE34: =ROUND(J34*(Q34/N34*0.8+U34/R34*0.2)*(Y34/V34),0) -> 349 | AF34: =AG34 -> 360.60378 | AG34: =VLOOKUP(B34,'[1]Jan-Dec'!$B$2:$AY$61,50,0) -> 360.60378 | AH34: =ROUND(J34*(Q34/N34*0.8+U34/R34*0.2)*(AC34/Z34),0) -> 0 | AJ34: =J34-AD34 -> 76 | AK34: =J34-AF34 -> 42.396222 | AM34: =ROUND(G34/J34,0) -> 470 | AO34: =IF(AM34>312,ROUND(AD34*0.1,0),0) -> 33 | AP34: =AD34+AO34 -> 360 | AQ34: =J34-AP34 -> 43 | AS34: =IF(AM34>312,ROUND(AF34*0.1,0),0) -> 36 | AT34: =AS34+AF34 -> 396.60378 | AU34: =J34-AT34 -> 6.3962224 | AW34: =IF(AF34*1.15>J34,ROUND(AF34*0.15,0),0) -> 54 | AX34: =AF34+AW34 -> 414.60378 | AY34: =J34-AX34 -> -11.603778 | BA34: =IF(AF34*1.2>J34,ROUND(AF34*0.2,0),0) -> 72 | BB34: =AF34+BA34 -> 432.60378 | BC34: =J34-BB34 -> -29.603778
A35: 경기도 양주시 | B35: 양주시 | C35: 시 | D35: 20~50만 이하 | E35: 50만 이하 | F35: 10부 | G35: 263610 | H35: 109 | I35: 283 | J35: 392 | K35: =기초자료!AV35/기초자료!I35 -> 0.91808461 | L35: =기초자료!AW35/기초자료!J35 -> 0.88169948 | M35: =기초자료!AX35/기초자료!K35 -> 0.89077163 | N35: =VLOOKUP(E35,'목표실차율, 안정적가동률'!$A$3:$C$9,3,FALSE) -> 0.49 | O35: =기초자료!CI35 -> 0.45462279 | P35: =기초자료!CJ35 -> 0.52895531 | Q35: =기초자료!CK35 -> 0.50985318 | R35: =VLOOKUP(E35,'목표실차율, 안정적가동률'!$F$3:$G$9,2,FALSE) -> 0.34 | S35: =기초자료!DV35 -> 0.32104549 | T35: =기초자료!DW35 -> 0.3767703 | U35: =기초자료!DX35 -> 0.36245002 | V35: =VLOOKUP(F35,'목표실차율, 안정적가동률'!$J$3:$L$6,3,FALSE) -> 0.88 | W35: =기초자료!FI35 -> 0.79911273 | X35: =기초자료!FJ35 -> 0.77305517 | Y35: =기초자료!FK35 -> 0.7797515 | Z35: =VLOOKUP(F35,'목표실차율, 안정적가동률'!$J$3:$L$6,3,FALSE) -> 0.88 | AA35: =기초자료!GP35 -> #DIV/0! | AB35: =기초자료!GQ35 -> #DIV/0! | AC35: =기초자료!GR35 -> 0 | AD35: =ROUND(J35*(Q35/N35)*(Y35/V35),0) -> 361 | AE35: =ROUND(J35*(Q35/N35*0.8+U35/R35*0.2)*(Y35/V35),0) -> 363 | AF35: =AG35 -> 402.16937 | AG35: =VLOOKUP(B35,'[1]Jan-Dec'!$B$2:$AY$61,50,0) -> 402.16937 | AH35: =ROUND(J35*(Q35/N35*0.8+U35/R35*0.2)*(AC35/Z35),0) -> 0 | AJ35: =J35-AD35 -> 31 | AK35: =J35-AF35 -> -10.169372 | AM35: =ROUND(G35/J35,0) -> 672 | AO35: =IF(AM35>312,ROUND(AD35*0.1,0),0) -> 36 | AP35: =AD35+AO35 -> 397 | AQ35: =J35-AP35 -> -5 | AS35: =IF(AM35>312,ROUND(AF35*0.1,0),0) -> 40 | AT35: =AS35+AF35 -> 442.16937 | AU35: =J35-AT35 -> -50.169372 | AW35: =IF(AF35*1.15>J35,ROUND(AF35*0.15,0),0) -> 60 | AX35: =AF35+AW35 -> 462.16937 | AY35: =J35-AX35 -> -70.169372 | BA35: =IF(AF35*1.2>J35,ROUND(AF35*0.2,0),0) -> 80 | BB35: =AF35+BA35 -> 482.16937 | BC35: =J35-BB35 -> -90.169372
A36: 경기도 양평군 | B36: 양평군 | C36: 군 | D36: 군지역 | E36: 군지역 | F36: 10부 | G36: 124241 | H36: 52 | I36: 161 | J36: 213 | K36: =기초자료!AV36/기초자료!I36 -> 0.91800071 | L36: =기초자료!AW36/기초자료!J36 -> 0.94560721 | M36: =기초자료!AX36/기초자료!K36 -> 0.93923648 | N36: =VLOOKUP(E36,'목표실차율, 안정적가동률'!$A$3:$C$9,3,FALSE) -> 0.46 | O36: =기초자료!CI36 -> 0.44105492 | P36: =기초자료!CJ36 -> 0.3806816 | Q36: =기초자료!CK36 -> 0.3942989 | R36: =VLOOKUP(E36,'목표실차율, 안정적가동률'!$F$3:$G$9,2,FALSE) -> 0.25 | S36: =기초자료!DV36 -> 0.30465867 | T36: =기초자료!DW36 -> 0.24607572 | U36: =기초자료!DX36 -> 0.2592892 | V36: =VLOOKUP(F36,'목표실차율, 안정적가동률'!$J$3:$L$6,3,FALSE) -> 0.88 | W36: =기초자료!FI36 -> 0.75935501 | X36: =기초자료!FJ36 -> 0.78081119 | Y36: =기초자료!FK36 -> 0.77597171 | Z36: =VLOOKUP(F36,'목표실차율, 안정적가동률'!$J$3:$L$6,3,FALSE) -> 0.88 | AA36: =기초자료!GP36 -> #DIV/0! | AB36: =기초자료!GQ36 -> #DIV/0! | AC36: =기초자료!GR36 -> 0 | AD36: =ROUND(J36*(Q36/N36)*(Y36/V36),0) -> 161 | AE36: =ROUND(J36*(Q36/N36*0.8+U36/R36*0.2)*(Y36/V36),0) -> 168 | AF36: =AE36 -> 168 | AG36: =VLOOKUP(B36,'[1]Jan-Dec'!$B$2:$AY$61,50,0) -> #N/A | AH36: =ROUND(J36*(Q36/N36*0.8+U36/R36*0.2)*(AC36/Z36),0) -> 0 | AJ36: =J36-AD36 -> 52 | AK36: =J36-AF36 -> 45 | AM36: =ROUND(G36/J36,0) -> 583 | AO36: =IF(AM36>312,ROUND(AD36*0.1,0),0) -> 16 | AP36: =AD36+AO36 -> 177 | AQ36: =J36-AP36 -> 36 | AS36: =IF(AM36>312,ROUND(AF36*0.1,0),0) -> 17 | AT36: =AS36+AF36 -> 185 | AU36: =J36-AT36 -> 28 | AW36: =IF(AF36*1.15>J36,ROUND(AF36*0.15,0),0) -> 0 | AX36: =AF36+AW36 -> 168 | AY36: =J36-AX36 -> 45 | BA36: =IF(AF36*1.2>J36,ROUND(AF36*0.2,0),0) -> 0 | BB36: =AF36+BA36 -> 168 | BC36: =J36-BB36 -> 45
A37: 경기도 여주시 | B37: 여주시 | C37: 시 | D37: 20만 이하 | E37: 20만 이하 | F37: 10부 | G37: 114253 | H37: 77 | I37: 165 | J37: 242 | K37: =기초자료!AV37/기초자료!I37 -> 1.0488525 | L37: =기초자료!AW37/기초자료!J37 -> 0.90957976 | M37: =기초자료!AX37/기초자료!K37 -> 0.94937197 | N37: =VLOOKUP(E37,'목표실차율, 안정적가동률'!$A$3:$C$9,3,FALSE) -> 0.48 | O37: =기초자료!CI37 -> 0.43559016 | P37: =기초자료!CJ37 -> 0.2775685 | Q37: =기초자료!CK37 -> 0.32744851 | R37: =VLOOKUP(E37,'목표실차율, 안정적가동률'!$F$3:$G$9,2,FALSE) -> 0.25 | S37: =기초자료!DV37 -> 0.26364857 | T37: =기초자료!DW37 -> 0.19439221 | U37: =기초자료!DX37 -> 0.21625319 | V37: =VLOOKUP(F37,'목표실차율, 안정적가동률'!$J$3:$L$6,3,FALSE) -> 0.88 | W37: =기초자료!FI37 -> 0.90646818 | X37: =기초자료!FJ37 -> 0.78552631 | Y37: =기초자료!FK37 -> 0.82370198 | Z37: =VLOOKUP(F37,'목표실차율, 안정적가동률'!$J$3:$L$6,3,FALSE) -> 0.88 | AA37: =기초자료!GP37 -> #DIV/0! | AB37: =기초자료!GQ37 -> #DIV/0! | AC37: =기초자료!GR37 -> 0 | AD37: =ROUND(J37*(Q37/N37)*(Y37/V37),0) -> 155 | AE37: =ROUND(J37*(Q37/N37*0.8+U37/R37*0.2)*(Y37/V37),0) -> 163 | AF37: =AG37 -> 168.18464 | AG37: =VLOOKUP(B37,'[1]Jan-Dec'!$B$2:$AY$61,50,0) -> 168.18464 | AH37: =ROUND(J37*(Q37/N37*0.8+U37/R37*0.2)*(AC37/Z37),0) -> 0 | AJ37: =J37-AD37 -> 87 | AK37: =J37-AF37 -> 73.815359 | AM37: =ROUND(G37/J37,0) -> 472 | AO37: =IF(AM37>312,ROUND(AD37*0.1,0),0) -> 16 | AP37: =AD37+AO37 -> 171 | AQ37: =J37-AP37 -> 71 | AS37: =IF(AM37>312,ROUND(AF37*0.1,0),0) -> 17 | AT37: =AS37+AF37 -> 185.18464 | AU37: =J37-AT37 -> 56.815359 | AW37: =IF(AF37*1.15>J37,ROUND(AF37*0.15,0),0) -> 0 | AX37: =AF37+AW37 -> 168.18464 | AY37: =J37-AX37 -> 73.815359 | BA37: =IF(AF37*1.2>J37,ROUND(AF37*0.2,0),0) -> 0 | BB37: =AF37+BA37 -> 168.18464 | BC37: =J37-BB37 -> 73.815359
A38: 경기도 연천군 | B38: 연천군 | C38: 군 | D38: 군지역 | E38: 군지역 | F38: 10부 | G38: 41705 | H38: 12 | I38: 49 | J38: 61 | K38: =기초자료!AV38/기초자료!I38 -> 0.94475111 | L38: =기초자료!AW38/기초자료!J38 -> 0.91926719 | M38: =기초자료!AX38/기초자료!K38 -> 0.92428042 | N38: =VLOOKUP(E38,'목표실차율, 안정적가동률'!$A$3:$C$9,3,FALSE) -> 0.46 | O38: =기초자료!CI38 -> 0.46761575 | P38: =기초자료!CJ38 -> 0.42188898 | Q38: =기초자료!CK38 -> 0.43108364 | R38: =VLOOKUP(E38,'목표실차율, 안정적가동률'!$F$3:$G$9,2,FALSE) -> 0.25 | S38: =기초자료!DV38 -> 0.2884429 | T38: =기초자료!DW38 -> 0.34304476 | U38: =기초자료!DX38 -> 0.33206552 | V38: =VLOOKUP(F38,'목표실차율, 안정적가동률'!$J$3:$L$6,3,FALSE) -> 0.88 | W38: =기초자료!FI38 -> 0.83079351 | X38: =기초자료!FJ38 -> 0.7647711 | Y38: =기초자료!FK38 -> 0.77804677 | Z38: =VLOOKUP(F38,'목표실차율, 안정적가동률'!$J$3:$L$6,3,FALSE) -> 0.88 | AA38: =기초자료!GP38 -> #DIV/0! | AB38: =기초자료!GQ38 -> #DIV/0! | AC38: =기초자료!GR38 -> 0 | AD38: =ROUND(J38*(Q38/N38)*(Y38/V38),0) -> 51 | AE38: =ROUND(J38*(Q38/N38*0.8+U38/R38*0.2)*(Y38/V38),0) -> 55 | AF38: =AE38 -> 55 | AG38: =VLOOKUP(B38,'[1]Jan-Dec'!$B$2:$AY$61,50,0) -> #N/A | AH38: =ROUND(J38*(Q38/N38*0.8+U38/R38*0.2)*(AC38/Z38),0) -> 0 | AJ38: =J38-AD38 -> 10 | AK38: =J38-AF38 -> 6 | AM38: =ROUND(G38/J38,0) -> 684 | AO38: =IF(AM38>312,ROUND(AD38*0.1,0),0) -> 5 | AP38: =AD38+AO38 -> 56 | AQ38: =J38-AP38 -> 5 | AS38: =IF(AM38>312,ROUND(AF38*0.1,0),0) -> 6 | AT38: =AS38+AF38 -> 61 | AU38: =J38-AT38 -> 0 | AW38: =IF(AF38*1.15>J38,ROUND(AF38*0.15,0),0) -> 8 | AX38: =AF38+AW38 -> 63 | AY38: =J38-AX38 -> -2 | BA38: =IF(AF38*1.2>J38,ROUND(AF38*0.2,0),0) -> 11 | BB38: =AF38+BA38 -> 66 | BC38: =J38-BB38 -> -5
A39: 경기도 용인시 | B39: 용인시 | C39: 시 | D39: 100~500만 이하 | E39: 200만 이하 | F39: 10부 | G39: 1077224 | H39: 337 | I39: 1580 | J39: 1917 | K39: =기초자료!AV39/기초자료!I39 -> 0.88282708 | L39: =기초자료!AW39/기초자료!J39 -> 0.87629382 | M39: =기초자료!AX39/기초자료!K39 -> 0.87722359 | N39: =VLOOKUP(E39,'목표실차율, 안정적가동률'!$A$3:$C$9,3,FALSE) -> 0.51 | O39: =기초자료!CI39 -> 0.58185203 | P39: =기초자료!CJ39 -> 0.52838089 | Q39: =기초자료!CK39 -> 0.53603918 | R39: =VLOOKUP(E39,'목표실차율, 안정적가동률'!$F$3:$G$9,2,FALSE) -> 0.45 | S39: =기초자료!DV39 -> 0.43673263 | T39: =기초자료!DW39 -> 0.38570434 | U39: =기초자료!DX39 -> 0.39301277 | V39: =VLOOKUP(F39,'목표실차율, 안정적가동률'!$J$3:$L$6,3,FALSE) -> 0.88 | W39: =기초자료!FI39 -> 0.86635664 | X39: =기초자료!FJ39 -> 0.74521136 | Y39: =기초자료!FK39 -> 0.76256216 | Z39: =VLOOKUP(F39,'목표실차율, 안정적가동률'!$J$3:$L$6,3,FALSE) -> 0.88 | AA39: =기초자료!GP39 -> #DIV/0! | AB39: =기초자료!GQ39 -> #DIV/0! | AC39: =기초자료!GR39 -> 0 | AD39: =ROUND(J39*(Q39/N39)*(Y39/V39),0) -> 1746 | AE39: =ROUND(J39*(Q39/N39*0.8+U39/R39*0.2)*(Y39/V39),0) -> 1687 | AF39: =AG39 -> 2054.0739 | AG39: =VLOOKUP(B39,'[1]Jan-Dec'!$B$2:$AY$61,50,0) -> 2054.0739 | AH39: =ROUND(J39*(Q39/N39*0.8+U39/R39*0.2)*(AC39/Z39),0) -> 0 | AJ39: =J39-AD39 -> 171 | AK39: =J39-AF39 -> -137.07385 | AM39: =ROUND(G39/J39,0) -> 562 | AO39: =IF(AM39>312,ROUND(AD39*0.1,0),0) -> 175 | AP39: =AD39+AO39 -> 1921 | AQ39: =J39-AP39 -> -4 | AS39: =IF(AM39>312,ROUND(AF39*0.1,0),0) -> 205 | AT39: =AS39+AF39 -> 2259.0739 | AU39: =J39-AT39 -> -342.07385 | AW39: =IF(AF39*1.15>J39,ROUND(AF39*0.15,0),0) -> 308 | AX39: =AF39+AW39 -> 2362.0739 | AY39: =J39-AX39 -> -445.07385 | BA39: =IF(AF39*1.2>J39,ROUND(AF39*0.2,0),0) -> 411 | BB39: =AF39+BA39 -> 2465.0739 | BC39: =J39-BB39 -> -548.07385
